Workbook

Sheet 26
A1: HSBC - Lee Su Hwei #175-244250-833 | E1: =E96 -> 2000.42 | F1: =F96 -> 3.03 | G1: =G96 -> 56202 | H1: =H96 -> 188626.62 | I1: =I96 -> 3.65
I2: HSBC One A/C
I3: #175-244250-832
A4: T-Date | B4: V-Date | C4: Description | D4: CQ# | E4: CNY | F4: GBP | G4: JPY S/A | H4: HKD S/A | I4: USD S/A
B5: 46023 | C5: Balance B/F | E5: ='25'!E444 -> 2000.42 | F5: ='25'!F444 -> 3.03 | G5: ='25'!G444 -> 1477 | H5: ='25'!H444 -> 34757.765 | I5: ='25'!I444 -> 3.65
B6: 46024 | C6: MDC S FG Martin Plac AUD13.7 @5.22773 | H6: -71.62
C7: cash rebate - 0.5% | H7: 0.37
C8: MDC S FG Martin Plac AUD61 @5.22786 | H8: -318.9
C9: cash rebate - 0.5% | H9: 1.62
C10: POS MDC - Fortress Travel | H10: -18
C11: cash rebate - 0.5% | H11: 0.09
C12: MDC S Yatai Rice Bow AUD16.19 @5.22791 | H12: -84.64
C13: cash rebate - 0.5% | H13: 0.42
C14: MDC S Yatai Rice Bow AUD0.2 @5.25 | H14: -1.05
C15: MDC S HFM Bowral AUD91.71 @5.25209 | H15: -481.67
C16: cash rebate - 0.5% | H16: 2.42
B17: 46027 | C17: POS MDC - Flywire Common Appeal | H17: -809.3
C18: cash rebate - 0.5% | H18: 4.05
B19: 46028 | C19: POS MDC - Flywire Common Appeal | H19: -768.35
C20: cash rebate - 0.5% | H20: 3.84
B21: 46031 | C21: POS MDC - Fortress Travel | H21: -38
C22: cash rebate - 0.5% | H22: 0.19
B23: 46032 | C23: POS MDC - Uber | H23: -55.62
C24: cash rebate - 0.5% | H24: 0.28
C25: POS MDC - Flywire Common Appeal | H25: -768.93
C26: cash rebate - 0.5% | H26: 3.84
B27: 46038 | C27: POS MDC - Paragon | H27: -616
C28: cash rebate - 0.5% | H28: 3.08
C29: POS MDC - Uber | H29: -85.87
C30: cash rebate - 0.5% | H30: 0.43
C31: POS MDC - Yakiniku Guu - Hysan | H31: -271
C32: cash rebate - 0.5% | H32: 1.36
B33: 46041 | C33: POS MDC - Uber | H33: -113.61
C34: cash rebate - 0.5% | H34: 0.57
B35: 46049 | C35: MDC S - Uber EUR3.96@9.33333 | H35: -36.4
C36: cash rebate - 0.52% | H36: 0.19
C37: MDC S - Uber EUR7.99@9.32540 | H37: -74.51
C38: cash rebate - 0.5% | H38: 0.37
C39: MDC S - Uber EUR11.98@9.32554 | H39: -111.72
C40: cash rebate - 0.5% | H40: 0.56
...

Sheet 25
A1: HSBC - Lee Su Hwei #175-244250-833
I2: HSBC One A/C
I3: #175-244250-832
A4: T-Date | B4: V-Date | C4: Description | D4: CQ# | E4: CNY | F4: GBP | G4: JPY S/A | H4: HKD S/A | I4: USD S/A
B5: 45658 | C5: Balance b/f | E5: ='24'!F132 -> 2000.22 | G5: ='24'!G132 -> 73969 | H5: ='24'!H132 -> 103155.92 | I5: ='24'!E132 -> 961.6
B6: 45665 | C6: MDC S - JD Sports Fash AUD90 @4.87511 | H6: =-90*4.87511 -> -438.7599
C7: cash rebate - 0.5% | H7: =ROUND(-H6*0.5%,2) -> 2.19
C8: MDC S - LS Lune Croiss AUD28.64 @4.87534 | H8: =-28.64*4.87534 -> -139.62974
C9: cash rebate - 0.49% | H9: =ROUND(-+H8*0.49%,2) -> 0.68
B10: 45666 | C10: MDC - TransportForns AUD3.2 @4.84062 | H10: =-3.2*4.84062 -> -15.489984
C11: cash rebate - 0.65% | H11: =ROUND(-H10*0.65%,2) -> 0.1
B12: 45667 | C12: MDC S - Zeus Rosebery AUD13.64 @4.8497 | H12: =-13.64*4.8497 -> -66.149908
C13: cash rebate - 0.52% | H13: =ROUND(-H12*0.52%,2) -> 0.34
C14: MDC S - Gelato Messinar AUD9.03@4.85492 | H14: =-9.03*4.85492 -> -43.839928
C15: cash rebate - 0.55% | H15: =ROUND(-H14*0.55%,2) -> 0.24
C16: MDC - TransportForns AUD4.48 @4.85267 | H16: =-4.48*4.85267 -> -21.739962
C17: cash rebate - 0.48% | H17: =ROUND(-H16*0.48%,2) -> 0.1
B18: 45668 | C18: To PayMe | H18: -700
C19: To PayMe | H19: -2000
C20: To PayMe | H20: -1300
C21: To PayMe | H21: -2000
C22: To PayMe | H22: -3000
C23: To PayMe | H23: -2000
B24: 45670 | C24: MDC - TransportForns AUD2.24 @4.83928 | H24: =-2.24*4.83928 -> -10.839987
C25: cash rebate - 0.5% | H25: =ROUND(-H24*0.5%,2) -> 0.05
B26: 45672 | C26: To PayMe | H26: -2160
C27: To PayMe | H27: -2000
B28: 45673 | C28: POS MDC - Fortress Travel | H28: -136.9
C29: cash rebate - 0.5% | H29: =ROUND(-+H28*0.5%,2) -> 0.68
B30: 45684 | C30: To PayMe | H30: -2500
C31: To PayMe | H31: -2000
C32: To PayMe | H32: -2000
C33: To PayMe | H33: -2000
B34: 45685 | C34: credit interest | H34: 20.1
E35: =SUM(E5:E34) -> 2000.22 | F35: =SUM(F5:F34) -> 0 | G35: =SUM(G5:G34) -> 73969 | H35: =SUM(H5:H34) -> 78647.051 | I35: =SUM(I5:I34) -> 961.6
B36: 45691 | C36: MDC S - Soilboy PTE LT SGD69 @5.79797 | H36: =-69*5.79797 -> -400.05993
C37: cash rebate - 0.508% | H37: =ROUND(-H36*0.508%,2) -> 2.03
B38: 45702 | C38: To PayMe | H38: -2000
C39: To PayMe | H39: -2000
B40: 45705 | C40: Ichiran HK Ltd | H40: -226
...

Sheet 24
A1: HSBC - Lee Su Hwei #175-244250-833 | E1: =+E132 -> 961.6 | F1: =+F132 -> 2000.22 | G1: =+G132 -> 73969 | H1: =+H132 -> 103155.92
E2: HSBC One A/C
E3: #175-244250-832
A4: T-Date | B4: V-Date | C4: Description | D4: CQ# | E4: USD S/A | F4: CNY | G4: JPY S/A | H4: HKD S/A
B5: 45292 | C5: Balance b/f | E5: =+'23'!E90 -> 961.6 | F5: =+'23'!F90 -> 2000.02 | G5: =+'23'!G90 -> 79042 | H5: =+'23'!H90 -> 276558.74
B6: 45296 | C6: MDC S TFL Travel - GBP2.7 @9.97777 | H6: =ROUND(-2.7*9.97777,2) -> -26.94
B7: =+B6 -> 45296 | C7: cash rebate - 0.4% | H7: =ROUND(-H6*0.4%,2)-0.01 -> 0.1
B8: 45297 | C8: MDC S TFL Travel - GBP2.8 @10.0428 | H8: =ROUND(-2.8*10.0428,2) -> -28.12
B9: =+B8 -> 45297 | C9: cash rebate - 0.4% | H9: =ROUND(-H8*0.4%,2)-0.01 -> 0.1
B10: 45297 | C10: Fortress Travel | H10: -33
B11: =+B10 -> 45297 | C11: cash rebate - 0.5% | H11: =ROUND(-H10*0.5%,2) -> 0.17
B12: 45299 | C12: To PayMe | H12: -16480
B13: 45299 | C13: To PayMe | H13: -2000
B14: 45302 | C14: POS MDC - The HK Ophtalmic | H14: -1300
B15: =+B14 -> 45302 | C15: cash rebate - 0.5% | H15: =ROUND(-H14*0.5%,2) -> 6.5
B16: 45302 | C16: To PayMe | H16: -3800
B17: 45302 | C17: To PayMe | H17: -2000
B18: 45303 | C18: POS MDC - Shake Shack | H18: -156
B19: =+B18 -> 45303 | C19: cash rebate - 0.5% | H19: =ROUND(-H18*0.5%,2) -> 0.78
B20: 45303 | C20: POS MDC - Shake Shack | H20: -148
B21: =+B20 -> 45303 | C21: cash rebate - 0.5% | H21: =ROUND(-H20*0.5%,2) -> 0.74
B22: 45303 | C22: POS MDC - Geforce Now TWD299 @0.2519 | H22: =ROUND(-299*0.2519,2) -> -75.32
B23: =+B22 -> 45303 | C23: cash rebate - 0.5% | H23: =ROUND(-H22*0.5%,2) -> 0.38
B24: 45311 | C24: To PayMe | H24: -6530
B25: 45311 | C25: To PayMe | H25: -2000
B26: 45313 | C26: To PayMe | H26: -2200
B27: 45313 | C27: To PayMe | H27: -2000
B28: 45318 | C28: credit interest | H28: 184.49
E29: =SUM(E5:E28) -> 961.6 | F29: =SUM(F5:F28) -> 2000.02 | G29: =SUM(G5:G28) -> 79042 | H29: =SUM(H5:H28) -> 237974.62
B30: 45327 | C30: To PayMe | H30: -4300
B31: 45327 | C31: To PayMe | H31: -2000
B32: 45327 | C32: To PayMe | H32: -1600
B33: 45327 | C33: To PayMe | H33: -2000
B34: 45328 | C34: POS MDC - Fortress Travel | H34: -33
B35: =+B34 -> 45328 | C35: cash rebate - 0.5% | H35: =ROUND(-H34*0.5%,2) -> 0.17
B36: 45338 | C36: POS MDC - Geforce Now TWD299 @0.24946 | H36: =ROUND(-299*0.24946,2) -> -74.59
B37: =+B36 -> 45338 | C37: cash rebate - 0.5% | H37: =ROUND(-H36*0.5%,2) -> 0.37
B38: 45350 | C38: credit interest | H38: 176.61
E39: =SUM(E29:E38) -> 961.6 | F39: =SUM(F29:F38) -> 2000.02 | G39: =SUM(G29:G38) -> 79042 | H39: =SUM(H29:H38) -> 228144.18
B40: 45362 | C40: POS MDC - Geforce Now TWD299 @0.24946 | H40: =ROUND(-299*0.24946,2) -> -74.59 | I40: game
...

Sheet 23
A1: HSBC - Lee Su Hwei #175-244250-833 | E1: =+E90 -> 961.6 | F1: =+F90 -> 2000.02 | G1: =+G90 -> 79042 | H1: =+H90 -> 276558.74
E2: HSBC One A/C
E3: #175-244250-832
A4: T-Date | B4: V-Date | C4: Description | D4: CQ# | E4: USD S/A | F4: CNY | G4: JPY S/A | H4: HKD S/A | M4: HKD/USD | O4: JPY/HKD | Q4: CNY/HKD
B5: 44927 | C5: Balance b/f | E5: =+'22'!E35 -> 961.6 | H5: =+'22'!F35 -> 360178.1
B6: 44954 | C6: credit interest | H6: 191.55
E7: =SUM(E5:E6) -> 961.6 | H7: =SUM(H5:H6) -> 360369.65 | J7: 367906.72 | K7: 44957 | L7: =+H7+ROUND(E7*M7,2)-J7 -> 0 | M7: 7.83805 | N7: =+ROUND(E7*M7,2) -> 7537.07
B8: 44985 | C8: credit interest | H8: 191.65
E9: =SUM(E7:E8) -> 961.6 | H9: =SUM(H7:H8) -> 360561.3 | J9: 368108.42 | K9: 44985 | L9: =+H9+ROUND(E9*M9,2)-J9 -> 0 | M9: 7.8485 | N9: =+ROUND(E9*M9,2) -> 7547.12
B10: 45000 | C10: paper statement annual fee | H10: -20
B11: 45013 | C11: credit interest | H11: 173.18
E12: =SUM(E9:E11) -> 961.6 | H12: =SUM(H9:H11) -> 360714.48 | J12: 368262.99 | K12: 45016 | L12: =+H12+ROUND(E12*M12,2)-J12 -> 0 | M12: 7.84995 | N12: =+ROUND(E12*M12,2) -> 7548.51
B13: 45044 | C13: credit interest | H13: 191.83
E14: =SUM(E12:E13) -> 961.6 | H14: =SUM(H12:H13) -> 360906.31 | J14: 368454.82 | K14: 45046 | L14: =+H14+ROUND(E14*M14,2)-J14 -> 0 | M14: 7.84995 | N14: =+ROUND(E14*M14,2) -> 7548.51
B15: 45073 | C15: credit interest | H15: 206.75
E16: =SUM(E14:E15) -> 961.6 | H16: =SUM(H14:H15) -> 361113.06 | J16: 368645.13 | K16: 45077 | L16: =+H16+ROUND(E16*M16,2)-J16 -> 0 | M16: 7.83285 | N16: =+ROUND(E16*M16,2) -> 7532.07
B17: 45090 | C17: FX JPY | G17: 88295 | H17: -5000 | P17: =-H17/G17 -> 0.056628348
B18: =B19 -> 45091 | C18: Fortress - misc | H18: -50 | R18: Dining | S18: =-SUM(H20:H21) -> 57.77
B19: 45091 | C19: cash rebate - 0.4% | H19: =ROUND(-H18*0.4%,2) -> 0.2 | R19: Misc. | S19: =-SUM(H18:H19)-SUM(H22:H31)-SUM(P26:P29) -> 1199.26
B20: =B21 -> 45091 | C20: Fuel Espresso Landma - dining | H20: -58 | S20: =SUM(S18:S19) -> 1257.03
B21: =B18 -> 45091 | C21: cash rebate - 0.4% | H21: =ROUND(-H20*0.4%,2) -> 0.23
B22: =B20 -> 45091 | C22: Fortress - misc | H22: -150
B23: =B22 -> 45091 | C23: cash rebate - 0.4% | H23: =ROUND(-H22*0.4%,2) -> 0.6
B24: 45091 | C24: Casetagram Ltd - misc | H24: -458
B25: =B24 -> 45091 | C25: cash rebate - 0.4% | H25: =ROUND(-H24*0.4%,2) -> 1.83
B26: 45096 | C26: MDC S Haneda Airport Ter - misc | G26: -1120 | P26: =ROUND(G26*$P$17,2) -> -63.42
B27: =+B26 -> 45096 | C27: cash rebate - 0.4% | G27: =ROUND(-G26*0.4%,0) -> 4 | P27: =ROUND(G27*$P$17,2) -> 0.23
B28: 45097 | C28: MDC S Haneda Airport Ter - misc | G28: -8170 | P28: =ROUND(G28*$P$17,2) -> -462.65
B29: =+B28 -> 45097 | C29: cash rebate - 0.4% | G29: =ROUND(-G28*0.4%,0) -> 33 | P29: =ROUND(G29*$P$17,2) -> 1.87
A30: 45099 | B30: 45100 | C30: POS MDC - Fortress Travel - misc | H30: -20
B31: =B30 -> 45100 | C31: cash rebate - 0.4% | H31: =ROUND(-H30*0.4%,2) -> 0.08
B32: 45105 | C32: credit interest | H32: 236.09
E33: =SUM(E16:E32) -> 961.6 | G33: =SUM(G16:G32) -> 79042 | H33: =SUM(H16:H32) -> 355616.09 | J33: 367431.06 | K33: 45107 | L33: =+H33+ROUND(E33*M33,2)+ROUND(G33*O33,2)-J33 -> -0.03 | M33: 7.83595 | N33: =+ROUND(E33*M33,2) -> 7535.05 | O33: 0.054147 | P33: =+ROUND(G33*O33,2) -> 4279.89
B34: 45110 | C34: POS MDC - Fortress Travel - misc | H34: -101 | R34: Dining | S34: =-SUM(H42:H43) -> 139.37
B35: =+B34 -> 45110 | C35: cash rebate - 0.4% | H35: =ROUND(-H34*0.4%,2) -> 0.4 | R35: Misc. | S35: =-SUM(H34:H35)-SUM(H48:H51) -> 241.04
B36: 45110 | C36: POS MDC - Uniqlo | H36: -238 | R36: Food | S36: =-SUM(H44:H47) -> 913.62
B37: =+B36 -> 45110 | C37: cash rebate - 0.4% | H37: =ROUND(-H36*0.4%,2) -> 0.95 | R37: Show | S37: =-SUM(H40:H41) -> 566.72
B38: 45110 | C38: POS MDC - Mannings | H38: -67.8 | R38: Groceries | S38: =-SUM(H38:H39) -> 67.53
B39: =+B38 -> 45110 | C39: cash rebate - 0.4% | H39: =ROUND(-H38*0.4%,2) -> 0.27 | R39: Clothes | S39: =-SUM(H36:H37) -> 237.05
B40: 45111 | C40: POS MDC - CD warehouse | H40: -569 | S40: =SUM(S34:S39) -> 2165.33
...

Sheet 22
A1: HSBC - Lee Su Hwei #175-244250-833
E2: HSBC One A/C
E3: #175-244250-833
A4: T-Date | B4: V-Date | C4: Description | D4: CQ# | E4: USD S/A | F4: HKD S/A | J4: HKD/USD
B5: 44562 | C5: Balance b/f | F5: =+'21'!E55 -> 383521.67
B6: 44589 | C6: credit interest | F6: =383522.32-383521.67 -> 0.65
F7: =SUM(F5:F6) -> 383522.32 | G7: 383522.32 | H7: 44592 | I7: =+G7-F7 -> 0
B8: 44620 | C8: credit interest | F8: =383522.97-383522.32 -> 0.65
F9: =SUM(F7:F8) -> 383522.97 | G9: 383522.97 | H9: 44620 | I9: =+G9-F9 -> 0
B10: 44648 | C10: credit interest | F10: =383523.56-383522.97 -> 0.59
F11: =SUM(F9:F10) -> 383523.56 | G11: 383523.56 | H11: 44651 | I11: =+G11-F11 -> 0
B12: 44679 | C12: credit interest | F12: 0.65
F13: =SUM(F11:F12) -> 383524.21 | G13: 383524.21 | H13: 44681 | I13: =+G13-F13 -> 0
B14: 44705 | C14: To PayMe | F14: -5000
B15: 44709 | C15: credit interest | F15: =5000-4999.37 -> 0.63
F16: =SUM(F13:F15) -> 378524.84 | G16: 378524.84 | H16: 44712 | I16: =+G16-F16 -> 0
B17: 44740 | C17: credit interest | F17: 0.65
F18: =SUM(F16:F17) -> 378525.49 | G18: 378525.49 | H18: 44742 | I18: =+G18-F18 -> 0
B19: 44770 | C19: credit interest | F19: 0.62
F20: =SUM(F18:F19) -> 378526.11 | G20: 378526.11 | H20: 44772 | I20: =+G20-F20 -> 0
B21: 44797 | C21: TR from #888 | E21: 1000
B22: 44800 | C22: credit interest | F22: 0.62
B23: 44803 | C23: Deposit | E23: 0.15
B24: 44803 | C24: MDC S SQ*The Thacher School | E24: -38.59
E25: =SUM(E20:E24) -> 961.56 | F25: =SUM(F20:F24) -> 378526.73 | G25: 386072.38 | H25: 44804 | I25: =+F25+ROUND(E25*J25,2)-G25 -> 0 | J25: 7.8473
B26: 44832 | C26: credit interest | F26: 7.09
E27: =SUM(E25:E26) -> 961.56 | F27: =SUM(F25:F26) -> 378533.82 | G27: 386081.92 | H27: 44834 | I27: =+F27+ROUND(E27*J27,2)-G27 -> 0 | J27: 7.84985
B28: 44862 | C28: credit interest | F28: 39.21
E29: =SUM(E27:E28) -> 961.56 | F29: =SUM(F27:F28) -> 378573.03 | G29: 386120.84 | H29: 44865 | I29: =+F29+ROUND(E29*J29,2)-G29 -> 0 | J29: 7.84955
B30: 44893 | C30: credit interest | F30: 102.75
E31: =SUM(E29:E30) -> 961.56 | F31: =SUM(F29:F30) -> 378675.78 | G31: 386179.75 | H31: 44895 | I31: =+F31+ROUND(E31*J31,2)-G31 -> 0 | J31: 7.80395 | K31: =+ROUND(E31*J31,2) -> 7503.97
B32: 44914 | C32: To PayMe | F32: -17489
B33: 44915 | C33: To PayMe | F33: -1154
B34: 44923 | C34: credit interest | E34: 0.04 | F34: 145.32
E35: =SUM(E31:E34) -> 961.6 | F35: =SUM(F31:F34) -> 360178.1 | G35: 367676.03 | H35: 44926 | I35: =+F35+ROUND(E35*J35,2)-G35 -> 0 | J35: 7.79735 | K35: =+ROUND(E35*J35,2) -> 7497.93
E37: =SUM(E35:E36) -> 961.6 | F37: =SUM(F35:F36) -> 360178.1 | G37: 367906.72 | H37: 44957 | I37: =+F37+ROUND(E37*J37,2)-G37 -> -191.55 | J37: 7.83805 | K37: =+ROUND(E37*J37,2) -> 7537.07

Sheet 21
A1: HSBC - Lee Su Hwei #175-244250-833
E2: HSBC One A/C
E3: #175-244250-833
A4: T-Date | B4: V-Date | C4: Description | D4: CQ# | E4: HKD S/A
A5: 44196 | B5: 44197 | C5: Balance b/f | E5: =+'20'!E24 -> 451606.8
B6: 44204 | C6: To Payme | E6: -2100
C7: To Payme | E7: -220
B8: 44207 | C8: To Payme | E8: -850
B9: 44208 | C9: To Payme | E9: -152
C10: To Payme | E10: -850
B11: 44214 | C11: To Payme | E11: -574
B12: 44216 | C12: To Payme | E12: -32
C13: To Payme | E13: -60
C14: To Payme | E14: -10
B15: 44224 | C15: credit interest | E15: 0.76
C16: To Payme | E16: =SUM(E5:E15) -> 446759.56
B17: 44228 | C17: To Payme | E17: -500
B18: 44232 | C18: To Payme | E18: -2650
B19: 44235 | C19: To Payme | E19: -6995
B20: 44237 | C20: To Payme | E20: -1000
C21: To Payme | E21: -500
B22: 44243 | C22: To Payme | E22: -19960
C23: To Payme | E23: -1704
B24: 44244 | C24: To Payme | E24: -15000
B25: 44247 | C25: To Payme | E25: -1209
B26: 44254 | C26: credit interest | E26: 0.7
E27: =SUM(E16:E26) -> 397242.26
B28: 44256 | C28: To Payme | E28: -570
B29: 44264 | C29: To Payme | E29: -380
B30: 44264 | C30: To Payme | E30: -168
B31: 44267 | C31: To Payme | E31: -2516
B32: 44282 | C32: credit interest | E32: 0.61
C33: To Payme | E33: -4062
B34: 44286 | C34: To Payme | E34: -950
E35: =SUM(E27:E34) -> 388596.87 | F35: 388596.87 | G35: 44286 | H35: =+F35-E35 -> 0
B36: 44293 | C36: To Payme | E36: -4861
B37: =B36 -> 44293 | C37: To Payme | E37: -220
B38: 44314 | C38: credit interest | E38: 0.68
E39: =SUM(E35:E38) -> 383516.55 | F39: 383516.55 | G39: 44316 | H39: =+F39-E39 -> 0
B40: 44344 | C40: credit interest | E40: 0.63
...

Sheet 20
A1: HSBC - Lee Su Hwei #175-244250-833 | E1: HSBC One A/C
E2: #175-244250-833
A3: T-Date | B3: V-Date | C3: Description | D3: CQ# | E3: HKD S/A
B4: 44125 | C4: initial deposit for #833 account opening | E4: 500000
B5: 44132 | C5: interest | E5: 0.19
E6: =SUM(E4:E5) -> 500000.19
B7: 44141 | C7: To Payme | E7: -1380
B8: 44141 | C8: To Payme | E8: -5500
B9: 44155 | C9: To Payme | E9: -9860
B10: 44161 | C10: To Payme | E10: -435
B11: 44163 | C11: interest | E11: 0.83
E12: =SUM(E6:E11) -> 482826.02
B13: 44174 | C13: To Payme | E13: -1488
B14: 44175 | C14: To Payme | E14: -670
B15: 44181 | C15: To Payme | E15: -5858
B16: 44181 | C16: To Payme | E16: -428
B17: 44182 | C17: To Payme | E17: -1022
B18: 44182 | C18: To Payme | E18: -2250
B19: 44183 | C19: To Payme | E19: -1758
B20: 44193 | C20: interest | E20: 0.78
B21: 44193 | C21: To Payme | E21: -12361
B22: 44195 | C22: To Payme | E22: -4800
B23: 44195 | C23: To Payme | E23: -585
E24: =SUM(E12:E23) -> 451606.8
