Workbook

Sheet Dashboard
A1: American Express Spend Report
A2: Clean summary of imported card statements.
A4: Statements | D4: Transactions | G4: Spend HKD
A5: 19 | D5: =COUNTA('Amex Transactions'!$C:$C)-1 | G5: =SUMIF('Amex Transactions'!$G:$G,">0",'Amex Transactions'!$G:$G)
A7: Payments/Credits HKD | D7: Net HKD | G7: Review Items
A8: =SUMIF('Amex Transactions'!$G:$G,"<0",'Amex Transactions'!$G:$G) | D8: =SUM('Amex Transactions'!$G:$G) | G8: =COUNTIF('Amex Transactions'!$I:$I,"Check")
A10: Date Range | B10: 25 Aug 2024 to 25 Mar 2026
A12: Top Categories | E12: Recent Statements
A13: Category | B13: Spend HKD | E13: Date | F13: Statement | G13: Rows | H13: Review
A14: Uncategorised | B14: =SUMIFS('Amex Transactions'!$G:$G,'Amex Transactions'!$D:$D,"Uncategorised",'Amex Transactions'!$G:$G,">0") | E14: 46107 | F14: 20260326 statement.pdf | G14: 84 | H14: 21
A15: Clothes & Shoes | B15: =SUMIFS('Amex Transactions'!$G:$G,'Amex Transactions'!$D:$D,"Clothes & Shoes",'Amex Transactions'!$G:$G,">0") | E15: 46079 | F15: 20260226 statement.pdf | G15: 83 | H15: 31
A16: Travel | B16: =SUMIFS('Amex Transactions'!$G:$G,'Amex Transactions'!$D:$D,"Travel",'Amex Transactions'!$G:$G,">0") | E16: 46048 | F16: 20260126 statement.pdf | G16: 40 | H16: 17
A17: Hotel | B17: =SUMIFS('Amex Transactions'!$G:$G,'Amex Transactions'!$D:$D,"Hotel",'Amex Transactions'!$G:$G,">0") | E17: 46017 | F17: 20251226 statement.pdf | G17: 101 | H17: 45
A18: Dining out | B18: =SUMIFS('Amex Transactions'!$G:$G,'Amex Transactions'!$D:$D,"Dining out",'Amex Transactions'!$G:$G,">0") | E18: 45987 | F18: 20251126 statement.pdf | G18: 125 | H18: 31
A19: Wine | B19: =SUMIFS('Amex Transactions'!$G:$G,'Amex Transactions'!$D:$D,"Wine",'Amex Transactions'!$G:$G,">0") | E19: 45956 | F19: 20251026 statement.pdf | G19: 69 | H19: 24
A20: Housewares | B20: =SUMIFS('Amex Transactions'!$G:$G,'Amex Transactions'!$D:$D,"Housewares",'Amex Transactions'!$G:$G,">0") | E20: 45926 | F20: 20250926 statement.pdf | G20: 55 | H20: 20
A21: Salon | B21: =SUMIFS('Amex Transactions'!$G:$G,'Amex Transactions'!$D:$D,"Salon",'Amex Transactions'!$G:$G,">0") | E21: 45895 | F21: 20250826 statement.pdf | G21: 81 | H21: 19
A22: Groceries | B22: =SUMIFS('Amex Transactions'!$G:$G,'Amex Transactions'!$D:$D,"Groceries",'Amex Transactions'!$G:$G,">0") | E22: 45864 | F22: 20250726 statement.pdf | G22: 43 | H22: 1
A23: Beauty | B23: =SUMIFS('Amex Transactions'!$G:$G,'Amex Transactions'!$D:$D,"Beauty",'Amex Transactions'!$G:$G,">0") | E23: 45834 | F23: 20250626 statement.pdf | G23: 83 | H23: 32
A24: Airfare | B24: =SUMIFS('Amex Transactions'!$G:$G,'Amex Transactions'!$D:$D,"Airfare",'Amex Transactions'!$G:$G,">0")
A25: Fees | B25: =SUMIFS('Amex Transactions'!$G:$G,'Amex Transactions'!$D:$D,"Fees",'Amex Transactions'!$G:$G,">0")

Sheet Monthly Summary
A1: Monthly Summary
A2: Spend and payments by month.
A4: Month | B4: Transactions | C4: Spend HKD | D4: Payments/Credits HKD | E4: Net HKD | F4: Review Items
A5: 2024-08 | B5: =COUNTIFS('Amex Transactions'!$B:$B,">="&DATEVALUE(A5&"-01"),'Amex Transactions'!$B:$B,"<"&EDATE(DATEVALUE(A5&"-01"),1)) | C5: =SUMIFS('Amex Transactions'!$G:$G,'Amex Transactions'!$B:$B,">="&DATEVALUE(A5&"-01"),'Amex Transactions'!$B:$B,"<"&EDATE(DATEVALUE(A5&"-01"),1),'Amex Transactions'!$G:$G,">0") | D5: =SUMIFS('Amex Transactions'!$G:$G,'Amex Transactions'!$B:$B,">="&DATEVALUE(A5&"-01"),'Amex Transactions'!$B:$B,"<"&EDATE(DATEVALUE(A5&"-01"),1),'Amex Transactions'!$G:$G,"<0") | E5: =C5+D5 | F5: =COUNTIFS('Amex Transactions'!$B:$B,">="&DATEVALUE(A5&"-01"),'Amex Transactions'!$B:$B,"<"&EDATE(DATEVALUE(A5&"-01"),1),'Amex Transactions'!$I:$I,"Check")
A6: 2024-09 | B6: =COUNTIFS('Amex Transactions'!$B:$B,">="&DATEVALUE(A6&"-01"),'Amex Transactions'!$B:$B,"<"&EDATE(DATEVALUE(A6&"-01"),1)) | C6: =SUMIFS('Amex Transactions'!$G:$G,'Amex Transactions'!$B:$B,">="&DATEVALUE(A6&"-01"),'Amex Transactions'!$B:$B,"<"&EDATE(DATEVALUE(A6&"-01"),1),'Amex Transactions'!$G:$G,">0") | D6: =SUMIFS('Amex Transactions'!$G:$G,'Amex Transactions'!$B:$B,">="&DATEVALUE(A6&"-01"),'Amex Transactions'!$B:$B,"<"&EDATE(DATEVALUE(A6&"-01"),1),'Amex Transactions'!$G:$G,"<0") | E6: =C6+D6 | F6: =COUNTIFS('Amex Transactions'!$B:$B,">="&DATEVALUE(A6&"-01"),'Amex Transactions'!$B:$B,"<"&EDATE(DATEVALUE(A6&"-01"),1),'Amex Transactions'!$I:$I,"Check")
A7: 2024-10 | B7: =COUNTIFS('Amex Transactions'!$B:$B,">="&DATEVALUE(A7&"-01"),'Amex Transactions'!$B:$B,"<"&EDATE(DATEVALUE(A7&"-01"),1)) | C7: =SUMIFS('Amex Transactions'!$G:$G,'Amex Transactions'!$B:$B,">="&DATEVALUE(A7&"-01"),'Amex Transactions'!$B:$B,"<"&EDATE(DATEVALUE(A7&"-01"),1),'Amex Transactions'!$G:$G,">0") | D7: =SUMIFS('Amex Transactions'!$G:$G,'Amex Transactions'!$B:$B,">="&DATEVALUE(A7&"-01"),'Amex Transactions'!$B:$B,"<"&EDATE(DATEVALUE(A7&"-01"),1),'Amex Transactions'!$G:$G,"<0") | E7: =C7+D7 | F7: =COUNTIFS('Amex Transactions'!$B:$B,">="&DATEVALUE(A7&"-01"),'Amex Transactions'!$B:$B,"<"&EDATE(DATEVALUE(A7&"-01"),1),'Amex Transactions'!$I:$I,"Check")
A8: 2024-11 | B8: =COUNTIFS('Amex Transactions'!$B:$B,">="&DATEVALUE(A8&"-01"),'Amex Transactions'!$B:$B,"<"&EDATE(DATEVALUE(A8&"-01"),1)) | C8: =SUMIFS('Amex Transactions'!$G:$G,'Amex Transactions'!$B:$B,">="&DATEVALUE(A8&"-01"),'Amex Transactions'!$B:$B,"<"&EDATE(DATEVALUE(A8&"-01"),1),'Amex Transactions'!$G:$G,">0") | D8: =SUMIFS('Amex Transactions'!$G:$G,'Amex Transactions'!$B:$B,">="&DATEVALUE(A8&"-01"),'Amex Transactions'!$B:$B,"<"&EDATE(DATEVALUE(A8&"-01"),1),'Amex Transactions'!$G:$G,"<0") | E8: =C8+D8 | F8: =COUNTIFS('Amex Transactions'!$B:$B,">="&DATEVALUE(A8&"-01"),'Amex Transactions'!$B:$B,"<"&EDATE(DATEVALUE(A8&"-01"),1),'Amex Transactions'!$I:$I,"Check")
A9: 2024-12 | B9: =COUNTIFS('Amex Transactions'!$B:$B,">="&DATEVALUE(A9&"-01"),'Amex Transactions'!$B:$B,"<"&EDATE(DATEVALUE(A9&"-01"),1)) | C9: =SUMIFS('Amex Transactions'!$G:$G,'Amex Transactions'!$B:$B,">="&DATEVALUE(A9&"-01"),'Amex Transactions'!$B:$B,"<"&EDATE(DATEVALUE(A9&"-01"),1),'Amex Transactions'!$G:$G,">0") | D9: =SUMIFS('Amex Transactions'!$G:$G,'Amex Transactions'!$B:$B,">="&DATEVALUE(A9&"-01"),'Amex Transactions'!$B:$B,"<"&EDATE(DATEVALUE(A9&"-01"),1),'Amex Transactions'!$G:$G,"<0") | E9: =C9+D9 | F9: =COUNTIFS('Amex Transactions'!$B:$B,">="&DATEVALUE(A9&"-01"),'Amex Transactions'!$B:$B,"<"&EDATE(DATEVALUE(A9&"-01"),1),'Amex Transactions'!$I:$I,"Check")
A10: 2025-01 | B10: =COUNTIFS('Amex Transactions'!$B:$B,">="&DATEVALUE(A10&"-01"),'Amex Transactions'!$B:$B,"<"&EDATE(DATEVALUE(A10&"-01"),1)) | C10: =SUMIFS('Amex Transactions'!$G:$G,'Amex Transactions'!$B:$B,">="&DATEVALUE(A10&"-01"),'Amex Transactions'!$B:$B,"<"&EDATE(DATEVALUE(A10&"-01"),1),'Amex Transactions'!$G:$G,">0") | D10: =SUMIFS('Amex Transactions'!$G:$G,'Amex Transactions'!$B:$B,">="&DATEVALUE(A10&"-01"),'Amex Transactions'!$B:$B,"<"&EDATE(DATEVALUE(A10&"-01"),1),'Amex Transactions'!$G:$G,"<0") | E10: =C10+D10 | F10: =COUNTIFS('Amex Transactions'!$B:$B,">="&DATEVALUE(A10&"-01"),'Amex Transactions'!$B:$B,"<"&EDATE(DATEVALUE(A10&"-01"),1),'Amex Transactions'!$I:$I,"Check")
A11: 2025-02 | B11: =COUNTIFS('Amex Transactions'!$B:$B,">="&DATEVALUE(A11&"-01"),'Amex Transactions'!$B:$B,"<"&EDATE(DATEVALUE(A11&"-01"),1)) | C11: =SUMIFS('Amex Transactions'!$G:$G,'Amex Transactions'!$B:$B,">="&DATEVALUE(A11&"-01"),'Amex Transactions'!$B:$B,"<"&EDATE(DATEVALUE(A11&"-01"),1),'Amex Transactions'!$G:$G,">0") | D11: =SUMIFS('Amex Transactions'!$G:$G,'Amex Transactions'!$B:$B,">="&DATEVALUE(A11&"-01"),'Amex Transactions'!$B:$B,"<"&EDATE(DATEVALUE(A11&"-01"),1),'Amex Transactions'!$G:$G,"<0") | E11: =C11+D11 | F11: =COUNTIFS('Amex Transactions'!$B:$B,">="&DATEVALUE(A11&"-01"),'Amex Transactions'!$B:$B,"<"&EDATE(DATEVALUE(A11&"-01"),1),'Amex Transactions'!$I:$I,"Check")
A12: 2025-03 | B12: =COUNTIFS('Amex Transactions'!$B:$B,">="&DATEVALUE(A12&"-01"),'Amex Transactions'!$B:$B,"<"&EDATE(DATEVALUE(A12&"-01"),1)) | C12: =SUMIFS('Amex Transactions'!$G:$G,'Amex Transactions'!$B:$B,">="&DATEVALUE(A12&"-01"),'Amex Transactions'!$B:$B,"<"&EDATE(DATEVALUE(A12&"-01"),1),'Amex Transactions'!$G:$G,">0") | D12: =SUMIFS('Amex Transactions'!$G:$G,'Amex Transactions'!$B:$B,">="&DATEVALUE(A12&"-01"),'Amex Transactions'!$B:$B,"<"&EDATE(DATEVALUE(A12&"-01"),1),'Amex Transactions'!$G:$G,"<0") | E12: =C12+D12 | F12: =COUNTIFS('Amex Transactions'!$B:$B,">="&DATEVALUE(A12&"-01"),'Amex Transactions'!$B:$B,"<"&EDATE(DATEVALUE(A12&"-01"),1),'Amex Transactions'!$I:$I,"Check")
A13: 2025-04 | B13: =COUNTIFS('Amex Transactions'!$B:$B,">="&DATEVALUE(A13&"-01"),'Amex Transactions'!$B:$B,"<"&EDATE(DATEVALUE(A13&"-01"),1)) | C13: =SUMIFS('Amex Transactions'!$G:$G,'Amex Transactions'!$B:$B,">="&DATEVALUE(A13&"-01"),'Amex Transactions'!$B:$B,"<"&EDATE(DATEVALUE(A13&"-01"),1),'Amex Transactions'!$G:$G,">0") | D13: =SUMIFS('Amex Transactions'!$G:$G,'Amex Transactions'!$B:$B,">="&DATEVALUE(A13&"-01"),'Amex Transactions'!$B:$B,"<"&EDATE(DATEVALUE(A13&"-01"),1),'Amex Transactions'!$G:$G,"<0") | E13: =C13+D13 | F13: =COUNTIFS('Amex Transactions'!$B:$B,">="&DATEVALUE(A13&"-01"),'Amex Transactions'!$B:$B,"<"&EDATE(DATEVALUE(A13&"-01"),1),'Amex Transactions'!$I:$I,"Check")
A14: 2025-05 | B14: =COUNTIFS('Amex Transactions'!$B:$B,">="&DATEVALUE(A14&"-01"),'Amex Transactions'!$B:$B,"<"&EDATE(DATEVALUE(A14&"-01"),1)) | C14: =SUMIFS('Amex Transactions'!$G:$G,'Amex Transactions'!$B:$B,">="&DATEVALUE(A14&"-01"),'Amex Transactions'!$B:$B,"<"&EDATE(DATEVALUE(A14&"-01"),1),'Amex Transactions'!$G:$G,">0") | D14: =SUMIFS('Amex Transactions'!$G:$G,'Amex Transactions'!$B:$B,">="&DATEVALUE(A14&"-01"),'Amex Transactions'!$B:$B,"<"&EDATE(DATEVALUE(A14&"-01"),1),'Amex Transactions'!$G:$G,"<0") | E14: =C14+D14 | F14: =COUNTIFS('Amex Transactions'!$B:$B,">="&DATEVALUE(A14&"-01"),'Amex Transactions'!$B:$B,"<"&EDATE(DATEVALUE(A14&"-01"),1),'Amex Transactions'!$I:$I,"Check")
A15: 2025-06 | B15: =COUNTIFS('Amex Transactions'!$B:$B,">="&DATEVALUE(A15&"-01"),'Amex Transactions'!$B:$B,"<"&EDATE(DATEVALUE(A15&"-01"),1)) | C15: =SUMIFS('Amex Transactions'!$G:$G,'Amex Transactions'!$B:$B,">="&DATEVALUE(A15&"-01"),'Amex Transactions'!$B:$B,"<"&EDATE(DATEVALUE(A15&"-01"),1),'Amex Transactions'!$G:$G,">0") | D15: =SUMIFS('Amex Transactions'!$G:$G,'Amex Transactions'!$B:$B,">="&DATEVALUE(A15&"-01"),'Amex Transactions'!$B:$B,"<"&EDATE(DATEVALUE(A15&"-01"),1),'Amex Transactions'!$G:$G,"<0") | E15: =C15+D15 | F15: =COUNTIFS('Amex Transactions'!$B:$B,">="&DATEVALUE(A15&"-01"),'Amex Transactions'!$B:$B,"<"&EDATE(DATEVALUE(A15&"-01"),1),'Amex Transactions'!$I:$I,"Check")
A16: 2025-07 | B16: =COUNTIFS('Amex Transactions'!$B:$B,">="&DATEVALUE(A16&"-01"),'Amex Transactions'!$B:$B,"<"&EDATE(DATEVALUE(A16&"-01"),1)) | C16: =SUMIFS('Amex Transactions'!$G:$G,'Amex Transactions'!$B:$B,">="&DATEVALUE(A16&"-01"),'Amex Transactions'!$B:$B,"<"&EDATE(DATEVALUE(A16&"-01"),1),'Amex Transactions'!$G:$G,">0") | D16: =SUMIFS('Amex Transactions'!$G:$G,'Amex Transactions'!$B:$B,">="&DATEVALUE(A16&"-01"),'Amex Transactions'!$B:$B,"<"&EDATE(DATEVALUE(A16&"-01"),1),'Amex Transactions'!$G:$G,"<0") | E16: =C16+D16 | F16: =COUNTIFS('Amex Transactions'!$B:$B,">="&DATEVALUE(A16&"-01"),'Amex Transactions'!$B:$B,"<"&EDATE(DATEVALUE(A16&"-01"),1),'Amex Transactions'!$I:$I,"Check")
... A24: 2026-03 | B24: =COUNTIFS('Amex Transactions'!$B:$B,">="&DATEVALUE(A24&"-01"),'Amex Transactions'!$B:$B,"<"&EDATE(DATEVALUE(A24&"-01"),1)) | C24: =SUMIFS('Amex Transactions'!$G:$G,'Amex Transactions'!$B:$B,">="&DATEVALUE(A24&"-01"),'Amex Transactions'!$B:$B,"<"&EDATE(DATEVALUE(A24&"-01"),1),'Amex Transactions'!$G:$G,">0") | D24: =SUMIFS('Amex Transactions'!$G:$G,'Amex Transactions'!$B:$B,">="&DATEVALUE(A24&"-01"),'Amex Transactions'!$B:$B,"<"&EDATE(DATEVALUE(A24&"-01"),1),'Amex Transactions'!$G:$G,"<0") | E24: =C24+D24 | F24: =COUNTIFS('Amex Transactions'!$B:$B,">="&DATEVALUE(A24&"-01"),'Amex Transactions'!$B:$B,"<"&EDATE(DATEVALUE(A24&"-01"),1),'Amex Transactions'!$I:$I,"Check")

Sheet Category Summary
A1: Category Summary
A2: Spend by owner and category.
A4: Belongs To | B4: Category | C4: Transactions | D4: Spend HKD | E4: Payments/Credits HKD | F4: Net HKD | G4: Review Items
A5: Family | B5: Airfare | C5: =COUNTIFS('Amex Transactions'!$E:$E,A5,'Amex Transactions'!$D:$D,B5) | D5: =SUMIFS('Amex Transactions'!$G:$G,'Amex Transactions'!$E:$E,A5,'Amex Transactions'!$D:$D,B5,'Amex Transactions'!$G:$G,">0") | E5: =SUMIFS('Amex Transactions'!$G:$G,'Amex Transactions'!$E:$E,A5,'Amex Transactions'!$D:$D,B5,'Amex Transactions'!$G:$G,"<0") | F5: =D5+E5 | G5: =COUNTIFS('Amex Transactions'!$E:$E,A5,'Amex Transactions'!$D:$D,B5,'Amex Transactions'!$I:$I,"Check")
A6: Family | B6: Art | C6: =COUNTIFS('Amex Transactions'!$E:$E,A6,'Amex Transactions'!$D:$D,B6) | D6: =SUMIFS('Amex Transactions'!$G:$G,'Amex Transactions'!$E:$E,A6,'Amex Transactions'!$D:$D,B6,'Amex Transactions'!$G:$G,">0") | E6: =SUMIFS('Amex Transactions'!$G:$G,'Amex Transactions'!$E:$E,A6,'Amex Transactions'!$D:$D,B6,'Amex Transactions'!$G:$G,"<0") | F6: =D6+E6 | G6: =COUNTIFS('Amex Transactions'!$E:$E,A6,'Amex Transactions'!$D:$D,B6,'Amex Transactions'!$I:$I,"Check")
A7: Family | B7: Beauty | C7: =COUNTIFS('Amex Transactions'!$E:$E,A7,'Amex Transactions'!$D:$D,B7) | D7: =SUMIFS('Amex Transactions'!$G:$G,'Amex Transactions'!$E:$E,A7,'Amex Transactions'!$D:$D,B7,'Amex Transactions'!$G:$G,">0") | E7: =SUMIFS('Amex Transactions'!$G:$G,'Amex Transactions'!$E:$E,A7,'Amex Transactions'!$D:$D,B7,'Amex Transactions'!$G:$G,"<0") | F7: =D7+E7 | G7: =COUNTIFS('Amex Transactions'!$E:$E,A7,'Amex Transactions'!$D:$D,B7,'Amex Transactions'!$I:$I,"Check")
A8: Family | B8: Book & Kindle | C8: =COUNTIFS('Amex Transactions'!$E:$E,A8,'Amex Transactions'!$D:$D,B8) | D8: =SUMIFS('Amex Transactions'!$G:$G,'Amex Transactions'!$E:$E,A8,'Amex Transactions'!$D:$D,B8,'Amex Transactions'!$G:$G,">0") | E8: =SUMIFS('Amex Transactions'!$G:$G,'Amex Transactions'!$E:$E,A8,'Amex Transactions'!$D:$D,B8,'Amex Transactions'!$G:$G,"<0") | F8: =D8+E8 | G8: =COUNTIFS('Amex Transactions'!$E:$E,A8,'Amex Transactions'!$D:$D,B8,'Amex Transactions'!$I:$I,"Check")
A9: Family | B9: Charity | C9: =COUNTIFS('Amex Transactions'!$E:$E,A9,'Amex Transactions'!$D:$D,B9) | D9: =SUMIFS('Amex Transactions'!$G:$G,'Amex Transactions'!$E:$E,A9,'Amex Transactions'!$D:$D,B9,'Amex Transactions'!$G:$G,">0") | E9: =SUMIFS('Amex Transactions'!$G:$G,'Amex Transactions'!$E:$E,A9,'Amex Transactions'!$D:$D,B9,'Amex Transactions'!$G:$G,"<0") | F9: =D9+E9 | G9: =COUNTIFS('Amex Transactions'!$E:$E,A9,'Amex Transactions'!$D:$D,B9,'Amex Transactions'!$I:$I,"Check")
A10: Family | B10: Clinic | C10: =COUNTIFS('Amex Transactions'!$E:$E,A10,'Amex Transactions'!$D:$D,B10) | D10: =SUMIFS('Amex Transactions'!$G:$G,'Amex Transactions'!$E:$E,A10,'Amex Transactions'!$D:$D,B10,'Amex Transactions'!$G:$G,">0") | E10: =SUMIFS('Amex Transactions'!$G:$G,'Amex Transactions'!$E:$E,A10,'Amex Transactions'!$D:$D,B10,'Amex Transactions'!$G:$G,"<0") | F10: =D10+E10 | G10: =COUNTIFS('Amex Transactions'!$E:$E,A10,'Amex Transactions'!$D:$D,B10,'Amex Transactions'!$I:$I,"Check")
A11: Family | B11: Clothes & Shoes | C11: =COUNTIFS('Amex Transactions'!$E:$E,A11,'Amex Transactions'!$D:$D,B11) | D11: =SUMIFS('Amex Transactions'!$G:$G,'Amex Transactions'!$E:$E,A11,'Amex Transactions'!$D:$D,B11,'Amex Transactions'!$G:$G,">0") | E11: =SUMIFS('Amex Transactions'!$G:$G,'Amex Transactions'!$E:$E,A11,'Amex Transactions'!$D:$D,B11,'Amex Transactions'!$G:$G,"<0") | F11: =D11+E11 | G11: =COUNTIFS('Amex Transactions'!$E:$E,A11,'Amex Transactions'!$D:$D,B11,'Amex Transactions'!$I:$I,"Check")
A12: Family | B12: Dining out | C12: =COUNTIFS('Amex Transactions'!$E:$E,A12,'Amex Transactions'!$D:$D,B12) | D12: =SUMIFS('Amex Transactions'!$G:$G,'Amex Transactions'!$E:$E,A12,'Amex Transactions'!$D:$D,B12,'Amex Transactions'!$G:$G,">0") | E12: =SUMIFS('Amex Transactions'!$G:$G,'Amex Transactions'!$E:$E,A12,'Amex Transactions'!$D:$D,B12,'Amex Transactions'!$G:$G,"<0") | F12: =D12+E12 | G12: =COUNTIFS('Amex Transactions'!$E:$E,A12,'Amex Transactions'!$D:$D,B12,'Amex Transactions'!$I:$I,"Check")
A13: Family | B13: Electronics | C13: =COUNTIFS('Amex Transactions'!$E:$E,A13,'Amex Transactions'!$D:$D,B13) | D13: =SUMIFS('Amex Transactions'!$G:$G,'Amex Transactions'!$E:$E,A13,'Amex Transactions'!$D:$D,B13,'Amex Transactions'!$G:$G,">0") | E13: =SUMIFS('Amex Transactions'!$G:$G,'Amex Transactions'!$E:$E,A13,'Amex Transactions'!$D:$D,B13,'Amex Transactions'!$G:$G,"<0") | F13: =D13+E13 | G13: =COUNTIFS('Amex Transactions'!$E:$E,A13,'Amex Transactions'!$D:$D,B13,'Amex Transactions'!$I:$I,"Check")
A14: Family | B14: Entertainment | C14: =COUNTIFS('Amex Transactions'!$E:$E,A14,'Amex Transactions'!$D:$D,B14) | D14: =SUMIFS('Amex Transactions'!$G:$G,'Amex Transactions'!$E:$E,A14,'Amex Transactions'!$D:$D,B14,'Amex Transactions'!$G:$G,">0") | E14: =SUMIFS('Amex Transactions'!$G:$G,'Amex Transactions'!$E:$E,A14,'Amex Transactions'!$D:$D,B14,'Amex Transactions'!$G:$G,"<0") | F14: =D14+E14 | G14: =COUNTIFS('Amex Transactions'!$E:$E,A14,'Amex Transactions'!$D:$D,B14,'Amex Transactions'!$I:$I,"Check")
A15: Family | B15: Fees | C15: =COUNTIFS('Amex Transactions'!$E:$E,A15,'Amex Transactions'!$D:$D,B15) | D15: =SUMIFS('Amex Transactions'!$G:$G,'Amex Transactions'!$E:$E,A15,'Amex Transactions'!$D:$D,B15,'Amex Transactions'!$G:$G,">0") | E15: =SUMIFS('Amex Transactions'!$G:$G,'Amex Transactions'!$E:$E,A15,'Amex Transactions'!$D:$D,B15,'Amex Transactions'!$G:$G,"<0") | F15: =D15+E15 | G15: =COUNTIFS('Amex Transactions'!$E:$E,A15,'Amex Transactions'!$D:$D,B15,'Amex Transactions'!$I:$I,"Check")
A16: Family | B16: Fitness Equipment | C16: =COUNTIFS('Amex Transactions'!$E:$E,A16,'Amex Transactions'!$D:$D,B16) | D16: =SUMIFS('Amex Transactions'!$G:$G,'Amex Transactions'!$E:$E,A16,'Amex Transactions'!$D:$D,B16,'Amex Transactions'!$G:$G,">0") | E16: =SUMIFS('Amex Transactions'!$G:$G,'Amex Transactions'!$E:$E,A16,'Amex Transactions'!$D:$D,B16,'Amex Transactions'!$G:$G,"<0") | F16: =D16+E16 | G16: =COUNTIFS('Amex Transactions'!$E:$E,A16,'Amex Transactions'!$D:$D,B16,'Amex Transactions'!$I:$I,"Check")
... A110: Su | B110: beauty | C110: =COUNTIFS('Amex Transactions'!$E:$E,A110,'Amex Transactions'!$D:$D,B110) | D110: =SUMIFS('Amex Transactions'!$G:$G,'Amex Transactions'!$E:$E,A110,'Amex Transactions'!$D:$D,B110,'Amex Transactions'!$G:$G,">0") | E110: =SUMIFS('Amex Transactions'!$G:$G,'Amex Transactions'!$E:$E,A110,'Amex Transactions'!$D:$D,B110,'Amex Transactions'!$G:$G,"<0") | F110: =D110+E110 | G110: =COUNTIFS('Amex Transactions'!$E:$E,A110,'Amex Transactions'!$D:$D,B110,'Amex Transactions'!$I:$I,"Check")

Sheet Merchant Summary
A1: Merchant Summary
A2: Largest merchants across all statements.
A4: Merchant | B4: Category | C4: Belongs To | D4: Transactions | E4: Spend HKD | F4: Last Date | G4: Review
A5: SILVERSEA LONDON | B5: =IFERROR(INDEX('Review Items'!$D:$D,MATCH(A5,'Review Items'!$B:$B,0)),IFERROR(INDEX('Rule Updates'!$B:$B,MATCH(A5,'Rule Updates'!$A:$A,0)),"Uncategorised")) | C5: =IFERROR(INDEX('Review Items'!$E:$E,MATCH(A5,'Review Items'!$B:$B,0)),IFERROR(INDEX('Rule Updates'!$C:$C,MATCH(A5,'Rule Updates'!$A:$A,0)),"Review")) | D5: =COUNTIF('Amex Transactions'!$C:$C,A5) | E5: =SUMIFS('Amex Transactions'!$G:$G,'Amex Transactions'!$C:$C,A5,'Amex Transactions'!$G:$G,">0") | F5: 45562 | G5: =IF(COUNTIFS('Amex Transactions'!$C:$C,A5,'Amex Transactions'!$I:$I,"Check")>0,"Check","")
A6: THE NET-A-PORTER GROUP HONG KONG | B6: =IFERROR(INDEX('Review Items'!$D:$D,MATCH(A6,'Review Items'!$B:$B,0)),IFERROR(INDEX('Rule Updates'!$B:$B,MATCH(A6,'Rule Updates'!$A:$A,0)),"Uncategorised")) | C6: =IFERROR(INDEX('Review Items'!$E:$E,MATCH(A6,'Review Items'!$B:$B,0)),IFERROR(INDEX('Rule Updates'!$C:$C,MATCH(A6,'Rule Updates'!$A:$A,0)),"Review")) | D6: =COUNTIF('Amex Transactions'!$C:$C,A6) | E6: =SUMIFS('Amex Transactions'!$G:$G,'Amex Transactions'!$C:$C,A6,'Amex Transactions'!$G:$G,">0") | F6: 46106 | G6: =IF(COUNTIFS('Amex Transactions'!$C:$C,A6,'Amex Transactions'!$I:$I,"Check")>0,"Check","")
A7: MYTHERESA APAC SERVICES ISLANDS | B7: =IFERROR(INDEX('Review Items'!$D:$D,MATCH(A7,'Review Items'!$B:$B,0)),IFERROR(INDEX('Rule Updates'!$B:$B,MATCH(A7,'Rule Updates'!$A:$A,0)),"Uncategorised")) | C7: =IFERROR(INDEX('Review Items'!$E:$E,MATCH(A7,'Review Items'!$B:$B,0)),IFERROR(INDEX('Rule Updates'!$C:$C,MATCH(A7,'Rule Updates'!$A:$A,0)),"Review")) | D7: =COUNTIF('Amex Transactions'!$C:$C,A7) | E7: =SUMIFS('Amex Transactions'!$G:$G,'Amex Transactions'!$C:$C,A7,'Amex Transactions'!$G:$G,">0") | F7: 46106 | G7: =IF(COUNTIFS('Amex Transactions'!$C:$C,A7,'Amex Transactions'!$I:$I,"Check")>0,"Check","")
A8: HTL*ASCOTTORCHARDS 800-468-3578 | B8: =IFERROR(INDEX('Review Items'!$D:$D,MATCH(A8,'Review Items'!$B:$B,0)),IFERROR(INDEX('Rule Updates'!$B:$B,MATCH(A8,'Rule Updates'!$A:$A,0)),"Uncategorised")) | C8: =IFERROR(INDEX('Review Items'!$E:$E,MATCH(A8,'Review Items'!$B:$B,0)),IFERROR(INDEX('Rule Updates'!$C:$C,MATCH(A8,'Rule Updates'!$A:$A,0)),"Review")) | D8: =COUNTIF('Amex Transactions'!$C:$C,A8) | E8: =SUMIFS('Amex Transactions'!$G:$G,'Amex Transactions'!$C:$C,A8,'Amex Transactions'!$G:$G,">0") | F8: 45572 | G8: =IF(COUNTIFS('Amex Transactions'!$C:$C,A8,'Amex Transactions'!$I:$I,"Check")>0,"Check","")
A9: WHALE CLU BHK | B9: =IFERROR(INDEX('Review Items'!$D:$D,MATCH(A9,'Review Items'!$B:$B,0)),IFERROR(INDEX('Rule Updates'!$B:$B,MATCH(A9,'Rule Updates'!$A:$A,0)),"Uncategorised")) | C9: =IFERROR(INDEX('Review Items'!$E:$E,MATCH(A9,'Review Items'!$B:$B,0)),IFERROR(INDEX('Rule Updates'!$C:$C,MATCH(A9,'Rule Updates'!$A:$A,0)),"Review")) | D9: =COUNTIF('Amex Transactions'!$C:$C,A9) | E9: =SUMIFS('Amex Transactions'!$G:$G,'Amex Transactions'!$C:$C,A9,'Amex Transactions'!$G:$G,">0") | F9: 46036 | G9: =IF(COUNTIFS('Amex Transactions'!$C:$C,A9,'Amex Transactions'!$I:$I,"Check")>0,"Check","")
A10: PONTI WINE CELLARS 0000 HONG KONG | B10: =IFERROR(INDEX('Review Items'!$D:$D,MATCH(A10,'Review Items'!$B:$B,0)),IFERROR(INDEX('Rule Updates'!$B:$B,MATCH(A10,'Rule Updates'!$A:$A,0)),"Uncategorised")) | C10: =IFERROR(INDEX('Review Items'!$E:$E,MATCH(A10,'Review Items'!$B:$B,0)),IFERROR(INDEX('Rule Updates'!$C:$C,MATCH(A10,'Rule Updates'!$A:$A,0)),"Review")) | D10: =COUNTIF('Amex Transactions'!$C:$C,A10) | E10: =SUMIFS('Amex Transactions'!$G:$G,'Amex Transactions'!$C:$C,A10,'Amex Transactions'!$G:$G,">0") | F10: 46097 | G10: =IF(COUNTIFS('Amex Transactions'!$C:$C,A10,'Amex Transactions'!$I:$I,"Check")>0,"Check","")
A11: LANE CRAWFORD (FURNITUR ADMIRALTY | B11: =IFERROR(INDEX('Review Items'!$D:$D,MATCH(A11,'Review Items'!$B:$B,0)),IFERROR(INDEX('Rule Updates'!$B:$B,MATCH(A11,'Rule Updates'!$A:$A,0)),"Uncategorised")) | C11: =IFERROR(INDEX('Review Items'!$E:$E,MATCH(A11,'Review Items'!$B:$B,0)),IFERROR(INDEX('Rule Updates'!$C:$C,MATCH(A11,'Rule Updates'!$A:$A,0)),"Review")) | D11: =COUNTIF('Amex Transactions'!$C:$C,A11) | E11: =SUMIFS('Amex Transactions'!$G:$G,'Amex Transactions'!$C:$C,A11,'Amex Transactions'!$G:$G,">0") | F11: 45799 | G11: =IF(COUNTIFS('Amex Transactions'!$C:$C,A11,'Amex Transactions'!$I:$I,"Check")>0,"Check","")
A12: RAFFLES HOTEL SINGAPORE SINGAPORE | B12: =IFERROR(INDEX('Review Items'!$D:$D,MATCH(A12,'Review Items'!$B:$B,0)),IFERROR(INDEX('Rule Updates'!$B:$B,MATCH(A12,'Rule Updates'!$A:$A,0)),"Uncategorised")) | C12: =IFERROR(INDEX('Review Items'!$E:$E,MATCH(A12,'Review Items'!$B:$B,0)),IFERROR(INDEX('Rule Updates'!$C:$C,MATCH(A12,'Rule Updates'!$A:$A,0)),"Review")) | D12: =COUNTIF('Amex Transactions'!$C:$C,A12) | E12: =SUMIFS('Amex Transactions'!$G:$G,'Amex Transactions'!$C:$C,A12,'Amex Transactions'!$G:$G,">0") | F12: 46074 | G12: =IF(COUNTIFS('Amex Transactions'!$C:$C,A12,'Amex Transactions'!$I:$I,"Check")>0,"Check","")
A13: AGORA IBIZA 367352630 SANT JOAN LAB | B13: =IFERROR(INDEX('Review Items'!$D:$D,MATCH(A13,'Review Items'!$B:$B,0)),IFERROR(INDEX('Rule Updates'!$B:$B,MATCH(A13,'Rule Updates'!$A:$A,0)),"Uncategorised")) | C13: =IFERROR(INDEX('Review Items'!$E:$E,MATCH(A13,'Review Items'!$B:$B,0)),IFERROR(INDEX('Rule Updates'!$C:$C,MATCH(A13,'Rule Updates'!$A:$A,0)),"Review")) | D13: =COUNTIF('Amex Transactions'!$C:$C,A13) | E13: =SUMIFS('Amex Transactions'!$G:$G,'Amex Transactions'!$C:$C,A13,'Amex Transactions'!$G:$G,">0") | F13: 45835 | G13: =IF(COUNTIFS('Amex Transactions'!$C:$C,A13,'Amex Transactions'!$I:$I,"Check")>0,"Check","")
A14: FAR FETCH LONDON | B14: =IFERROR(INDEX('Review Items'!$D:$D,MATCH(A14,'Review Items'!$B:$B,0)),IFERROR(INDEX('Rule Updates'!$B:$B,MATCH(A14,'Rule Updates'!$A:$A,0)),"Uncategorised")) | C14: =IFERROR(INDEX('Review Items'!$E:$E,MATCH(A14,'Review Items'!$B:$B,0)),IFERROR(INDEX('Rule Updates'!$C:$C,MATCH(A14,'Rule Updates'!$A:$A,0)),"Review")) | D14: =COUNTIF('Amex Transactions'!$C:$C,A14) | E14: =SUMIFS('Amex Transactions'!$G:$G,'Amex Transactions'!$C:$C,A14,'Amex Transactions'!$G:$G,">0") | F14: 46095 | G14: =IF(COUNTIFS('Amex Transactions'!$C:$C,A14,'Amex Transactions'!$I:$I,"Check")>0,"Check","")
A15: BURGUNDY ETC CENTRAL | B15: =IFERROR(INDEX('Review Items'!$D:$D,MATCH(A15,'Review Items'!$B:$B,0)),IFERROR(INDEX('Rule Updates'!$B:$B,MATCH(A15,'Rule Updates'!$A:$A,0)),"Uncategorised")) | C15: =IFERROR(INDEX('Review Items'!$E:$E,MATCH(A15,'Review Items'!$B:$B,0)),IFERROR(INDEX('Rule Updates'!$C:$C,MATCH(A15,'Rule Updates'!$A:$A,0)),"Review")) | D15: =COUNTIF('Amex Transactions'!$C:$C,A15) | E15: =SUMIFS('Amex Transactions'!$G:$G,'Amex Transactions'!$C:$C,A15,'Amex Transactions'!$G:$G,">0") | F15: 46003 | G15: =IF(COUNTIFS('Amex Transactions'!$C:$C,A15,'Amex Transactions'!$I:$I,"Check")>0,"Check","")
A16: 3CPAYMENT*SIX SENSES IB GETARIA | B16: =IFERROR(INDEX('Review Items'!$D:$D,MATCH(A16,'Review Items'!$B:$B,0)),IFERROR(INDEX('Rule Updates'!$B:$B,MATCH(A16,'Rule Updates'!$A:$A,0)),"Uncategorised")) | C16: =IFERROR(INDEX('Review Items'!$E:$E,MATCH(A16,'Review Items'!$B:$B,0)),IFERROR(INDEX('Rule Updates'!$C:$C,MATCH(A16,'Rule Updates'!$A:$A,0)),"Review")) | D16: =COUNTIF('Amex Transactions'!$C:$C,A16) | E16: =SUMIFS('Amex Transactions'!$G:$G,'Amex Transactions'!$C:$C,A16,'Amex Transactions'!$G:$G,">0") | F16: 45827 | G16: =IF(COUNTIFS('Amex Transactions'!$C:$C,A16,'Amex Transactions'!$I:$I,"Check")>0,"Check","")
... A692: TUMI ASIA LIMITED | B692: =IFERROR(INDEX('Review Items'!$D:$D,MATCH(A692,'Review Items'!$B:$B,0)),IFERROR(INDEX('Rule Updates'!$B:$B,MATCH(A692,'Rule Updates'!$A:$A,0)),"Uncategorised")) | C692: =IFERROR(INDEX('Review Items'!$E:$E,MATCH(A692,'Review Items'!$B:$B,0)),IFERROR(INDEX('Rule Updates'!$C:$C,MATCH(A692,'Rule Updates'!$A:$A,0)),"Review")) | D692: =COUNTIF('Amex Transactions'!$C:$C,A692) | E692: =SUMIFS('Amex Transactions'!$G:$G,'Amex Transactions'!$C:$C,A692,'Amex Transactions'!$G:$G,">0") | F692: 46076 | G692: =IF(COUNTIFS('Amex Transactions'!$C:$C,A692,'Amex Transactions'!$I:$I,"Check")>0,"Check","")

Sheet Review Items
A1: Review Items
A2: Live queue of transactions that started without a complete category/owner.
A4: Date | B4: Merchant | C4: Amount HKD | D4: Current Category | E4: Belongs To | F4: Statement | G4: Status
A5: 45529 | B5: AZABUDAIHILLS TOKYO | C5: 3640.51 | D5: Uncategorised | E5: Review | F5: Amex Sep-2024 | G5: =IF(OR(D5="Uncategorised",E5="",E5="Review"),"Needs category/owner","Resolved")
A6: 45536 | B6: LOOKOPTIC LOS ANGELES | C6: 1006.49 | D6: Uncategorised | E6: Review | F6: Amex Sep-2024 | G6: =IF(OR(D6="Uncategorised",E6="",E6="Review"),"Needs category/owner","Resolved")
A7: 45536 | B7: LOOKOPTIC LOS ANGELES | C7: 444.43 | D7: Uncategorised | E7: Review | F7: Amex Sep-2024 | G7: =IF(OR(D7="Uncategorised",E7="",E7="Review"),"Needs category/owner","Resolved")
A8: 45546 | B8: KPAY*MOMOGAWANOU 000000 HONG KONG | C8: 3340 | D8: Uncategorised | E8: Review | F8: Amex Sep-2024 | G8: =IF(OR(D8="Uncategorised",E8="",E8="Review"),"Needs category/owner","Resolved")
A9: 45562 | B9: SOGO HONG KONG CO LTD CAUSEWAY BAY | C9: 120 | D9: Uncategorised | E9: Review | F9: Amex Oct-2024 | G9: =IF(OR(D9="Uncategorised",E9="",E9="Review"),"Needs category/owner","Resolved")
A10: 45575 | B10: WWW.HYUNDAI.COM SINGAPORE | C10: 4742.32 | D10: Uncategorised | E10: Review | F10: Amex Oct-2024 | G10: =IF(OR(D10="Uncategorised",E10="",E10="Review"),"Needs category/owner","Resolved")
A11: 45576 | B11: Alice Pizza CTRL HK | C11: 261.1 | D11: Uncategorised | E11: Review | F11: Amex Oct-2024 | G11: =IF(OR(D11="Uncategorised",E11="",E11="Review"),"Needs category/owner","Resolved")
A12: 45588 | B12: WIX SQUARED LTD ST. MARTIN | C12: 32248.15 | D12: Uncategorised | E12: Review | F12: Amex Oct-2024 | G12: =IF(OR(D12="Uncategorised",E12="",E12="Review"),"Needs category/owner","Resolved")
A13: 45589 | B13: PARAGON CENTRAL | C13: 242 | D13: Uncategorised | E13: Review | F13: Amex Oct-2024 | G13: =IF(OR(D13="Uncategorised",E13="",E13="Review"),"Needs category/owner","Resolved")
A14: 45590 | B14: FIATA CENTRAL | C14: 627 | D14: Uncategorised | E14: Review | F14: Amex Oct-2024 | G14: =IF(OR(D14="Uncategorised",E14="",E14="Review"),"Needs category/owner","Resolved")
A15: 45622 | B15: CITEES CARTAGENACARMEN MURCIA | C15: 626.84 | D15: Uncategorised | E15: Review | F15: Amex Dec-2024 | G15: =IF(OR(D15="Uncategorised",E15="",E15="Review"),"Needs category/owner","Resolved")
A16: 45623 | B16: FARMACIA EL SAGRARIO 01 MALAGA | C16: 443.14 | D16: Uncategorised | E16: Review | F16: Amex Dec-2024 | G16: =IF(OR(D16="Uncategorised",E16="",E16="Review"),"Needs category/owner","Resolved")
... A386: 46104 | B386: KPAY * MAISON KARYA 00000 HONG KONG | C386: 1204.2 | D386: Uncategorised | E386: Review | F386: Amex Mar-2026 | G386: =IF(OR(D386="Uncategorised",E386="",E386="Review"),"Needs category/owner","Resolved")

Sheet Amex Transactions
A1: Amex Transactions
A2: Full transaction ledger.
A4: Statement | B4: Date | C4: Merchant | D4: Category | E4: Belongs To | F4: Foreign Spend | G4: Amount HKD | H4: Source Page | I4: Review
A5: Amex Sep-2024 | B5: 45529 | C5: AZABUDAIHILLS TOKYO | D5: =IFERROR(INDEX('Review Items'!$D:$D,MATCH(C5,'Review Items'!$B:$B,0)),IFERROR(INDEX('Rule Updates'!$B:$B,MATCH(C5,'Rule Updates'!$A:$A,0)),"Uncategorised")) | E5: =IFERROR(INDEX('Review Items'!$E:$E,MATCH(C5,'Review Items'!$B:$B,0)),IFERROR(INDEX('Rule Updates'!$C:$C,MATCH(C5,'Rule Updates'!$A:$A,0)),"Review")) | F5: 66340 | G5: 3640.51 | H5: 6 | I5: =IF(OR(D5="Uncategorised",E5=""),"Check","")
A6: Amex Sep-2024 | B6: 45531 | C6: AMATHUS (Bath) Bath | D6: =IFERROR(INDEX('Review Items'!$D:$D,MATCH(C6,'Review Items'!$B:$B,0)),IFERROR(INDEX('Rule Updates'!$B:$B,MATCH(C6,'Rule Updates'!$A:$A,0)),"Uncategorised")) | E6: =IFERROR(INDEX('Review Items'!$E:$E,MATCH(C6,'Review Items'!$B:$B,0)),IFERROR(INDEX('Rule Updates'!$C:$C,MATCH(C6,'Rule Updates'!$A:$A,0)),"Review")) | F6: 64.7 | G6: 679.91 | H6: 1 | I6: =IF(OR(D6="Uncategorised",E6=""),"Check","")
A7: Amex Sep-2024 | B7: 45531 | C7: Mr B's Emporium Bath | D7: =IFERROR(INDEX('Review Items'!$D:$D,MATCH(C7,'Review Items'!$B:$B,0)),IFERROR(INDEX('Rule Updates'!$B:$B,MATCH(C7,'Rule Updates'!$A:$A,0)),"Uncategorised")) | E7: =IFERROR(INDEX('Review Items'!$E:$E,MATCH(C7,'Review Items'!$B:$B,0)),IFERROR(INDEX('Rule Updates'!$C:$C,MATCH(C7,'Rule Updates'!$A:$A,0)),"Review")) | F7: 49.98 | G7: 525.22 | H7: 1 | I7: =IF(OR(D7="Uncategorised",E7=""),"Check","")
A8: Amex Sep-2024 | B8: 45531 | C8: TOPPING & COMPANY BOOKS Bathwick | D8: =IFERROR(INDEX('Review Items'!$D:$D,MATCH(C8,'Review Items'!$B:$B,0)),IFERROR(INDEX('Rule Updates'!$B:$B,MATCH(C8,'Rule Updates'!$A:$A,0)),"Uncategorised")) | E8: =IFERROR(INDEX('Review Items'!$E:$E,MATCH(C8,'Review Items'!$B:$B,0)),IFERROR(INDEX('Rule Updates'!$C:$C,MATCH(C8,'Rule Updates'!$A:$A,0)),"Review")) | F8: 26 | G8: 273.18 | H8: 1 | I8: =IF(OR(D8="Uncategorised",E8=""),"Check","")
A9: Amex Sep-2024 | B9: 45531 | C9: TOPPING & COMPANY BOOKS Bathwick | D9: =IFERROR(INDEX('Review Items'!$D:$D,MATCH(C9,'Review Items'!$B:$B,0)),IFERROR(INDEX('Rule Updates'!$B:$B,MATCH(C9,'Rule Updates'!$A:$A,0)),"Uncategorised")) | E9: =IFERROR(INDEX('Review Items'!$E:$E,MATCH(C9,'Review Items'!$B:$B,0)),IFERROR(INDEX('Rule Updates'!$C:$C,MATCH(C9,'Rule Updates'!$A:$A,0)),"Review")) | F9: 53.98 | G9: 567.22 | H9: 1 | I9: =IF(OR(D9="Uncategorised",E9=""),"Check","")
A10: Amex Sep-2024 | B10: 45531 | C10: WH SMITH TRAVEL RETAIL HOUNSLOW | D10: =IFERROR(INDEX('Review Items'!$D:$D,MATCH(C10,'Review Items'!$B:$B,0)),IFERROR(INDEX('Rule Updates'!$B:$B,MATCH(C10,'Rule Updates'!$A:$A,0)),"Uncategorised")) | E10: =IFERROR(INDEX('Review Items'!$E:$E,MATCH(C10,'Review Items'!$B:$B,0)),IFERROR(INDEX('Rule Updates'!$C:$C,MATCH(C10,'Rule Updates'!$A:$A,0)),"Review")) | F10: 15.74 | G10: 165.42 | H10: 1 | I10: =IF(OR(D10="Uncategorised",E10=""),"Check","")
A11: Amex Sep-2024 | B11: 45534 | C11: CLARINS LIMITED CENTRAL | D11: =IFERROR(INDEX('Review Items'!$D:$D,MATCH(C11,'Review Items'!$B:$B,0)),IFERROR(INDEX('Rule Updates'!$B:$B,MATCH(C11,'Rule Updates'!$A:$A,0)),"Uncategorised")) | E11: =IFERROR(INDEX('Review Items'!$E:$E,MATCH(C11,'Review Items'!$B:$B,0)),IFERROR(INDEX('Rule Updates'!$C:$C,MATCH(C11,'Rule Updates'!$A:$A,0)),"Review")) | G11: 3541 | H11: 2 | I11: =IF(OR(D11="Uncategorised",E11=""),"Check","")
A12: Amex Sep-2024 | B12: 45534 | C12: IL COLPO PACIFIC PLACE ADMIRALTY | D12: =IFERROR(INDEX('Review Items'!$D:$D,MATCH(C12,'Review Items'!$B:$B,0)),IFERROR(INDEX('Rule Updates'!$B:$B,MATCH(C12,'Rule Updates'!$A:$A,0)),"Uncategorised")) | E12: =IFERROR(INDEX('Review Items'!$E:$E,MATCH(C12,'Review Items'!$B:$B,0)),IFERROR(INDEX('Rule Updates'!$C:$C,MATCH(C12,'Rule Updates'!$A:$A,0)),"Review")) | G12: 4680 | H12: 2 | I12: =IF(OR(D12="Uncategorised",E12=""),"Check","")
A13: Amex Sep-2024 | B13: 45535 | C13: CITYSUPER STORE @ SOUTH WONG CHUK HANG | D13: =IFERROR(INDEX('Review Items'!$D:$D,MATCH(C13,'Review Items'!$B:$B,0)),IFERROR(INDEX('Rule Updates'!$B:$B,MATCH(C13,'Rule Updates'!$A:$A,0)),"Uncategorised")) | E13: =IFERROR(INDEX('Review Items'!$E:$E,MATCH(C13,'Review Items'!$B:$B,0)),IFERROR(INDEX('Rule Updates'!$C:$C,MATCH(C13,'Rule Updates'!$A:$A,0)),"Review")) | G13: 1728.9 | H13: 2 | I13: =IF(OR(D13="Uncategorised",E13=""),"Check","")
A14: Amex Sep-2024 | B14: 45536 | C14: AMAZON PRIME*RK2502SU0 AMZN.COM/BILL | D14: =IFERROR(INDEX('Review Items'!$D:$D,MATCH(C14,'Review Items'!$B:$B,0)),IFERROR(INDEX('Rule Updates'!$B:$B,MATCH(C14,'Rule Updates'!$A:$A,0)),"Uncategorised")) | E14: =IFERROR(INDEX('Review Items'!$E:$E,MATCH(C14,'Review Items'!$B:$B,0)),IFERROR(INDEX('Rule Updates'!$C:$C,MATCH(C14,'Rule Updates'!$A:$A,0)),"Review")) | F14: 14.99 | G14: 119.28 | H14: 2 | I14: =IF(OR(D14="Uncategorised",E14=""),"Check","")
A15: Amex Sep-2024 | B15: 45536 | C15: CITYSUPER STORE @ AIRSI KOWLOON CITY | D15: =IFERROR(INDEX('Review Items'!$D:$D,MATCH(C15,'Review Items'!$B:$B,0)),IFERROR(INDEX('Rule Updates'!$B:$B,MATCH(C15,'Rule Updates'!$A:$A,0)),"Uncategorised")) | E15: =IFERROR(INDEX('Review Items'!$E:$E,MATCH(C15,'Review Items'!$B:$B,0)),IFERROR(INDEX('Rule Updates'!$C:$C,MATCH(C15,'Rule Updates'!$A:$A,0)),"Review")) | G15: 413.3 | H15: 2 | I15: =IF(OR(D15="Uncategorised",E15=""),"Check","")
A16: Amex Sep-2024 | B16: 45536 | C16: EIGHTH DAY SKINCA SANTA ANA | D16: =IFERROR(INDEX('Review Items'!$D:$D,MATCH(C16,'Review Items'!$B:$B,0)),IFERROR(INDEX('Rule Updates'!$B:$B,MATCH(C16,'Rule Updates'!$A:$A,0)),"Uncategorised")) | E16: =IFERROR(INDEX('Review Items'!$E:$E,MATCH(C16,'Review Items'!$B:$B,0)),IFERROR(INDEX('Rule Updates'!$C:$C,MATCH(C16,'Rule Updates'!$A:$A,0)),"Review")) | F16: 925.26 | G16: 7362.97 | H16: 2 | I16: =IF(OR(D16="Uncategorised",E16=""),"Check","")
A17: Amex Sep-2024 | B17: 45536 | C17: EIGHTH DAY SKINCA SANTA ANA | D17: =IFERROR(INDEX('Review Items'!$D:$D,MATCH(C17,'Review Items'!$B:$B,0)),IFERROR(INDEX('Rule Updates'!$B:$B,MATCH(C17,'Rule Updates'!$A:$A,0)),"Uncategorised")) | E17: =IFERROR(INDEX('Review Items'!$E:$E,MATCH(C17,'Review Items'!$B:$B,0)),IFERROR(INDEX('Rule Updates'!$C:$C,MATCH(C17,'Rule Updates'!$A:$A,0)),"Review")) | F17: 728.17 | G17: 5794.57 | H17: 2 | I17: =IF(OR(D17="Uncategorised",E17=""),"Check","")
A18: Amex Sep-2024 | B18: 45536 | C18: EIGHTH DAY SKINCA SANTA ANA | D18: =IFERROR(INDEX('Review Items'!$D:$D,MATCH(C18,'Review Items'!$B:$B,0)),IFERROR(INDEX('Rule Updates'!$B:$B,MATCH(C18,'Rule Updates'!$A:$A,0)),"Uncategorised")) | E18: =IFERROR(INDEX('Review Items'!$E:$E,MATCH(C18,'Review Items'!$B:$B,0)),IFERROR(INDEX('Rule Updates'!$C:$C,MATCH(C18,'Rule Updates'!$A:$A,0)),"Review")) | F18: 235.43 | G18: 1873.48 | H18: 2 | I18: =IF(OR(D18="Uncategorised",E18=""),"Check","")
A19: Amex Sep-2024 | B19: 45536 | C19: LOOKOPTIC LOS ANGELES | D19: =IFERROR(INDEX('Review Items'!$D:$D,MATCH(C19,'Review Items'!$B:$B,0)),IFERROR(INDEX('Rule Updates'!$B:$B,MATCH(C19,'Rule Updates'!$A:$A,0)),"Uncategorised")) | E19: =IFERROR(INDEX('Review Items'!$E:$E,MATCH(C19,'Review Items'!$B:$B,0)),IFERROR(INDEX('Rule Updates'!$C:$C,MATCH(C19,'Rule Updates'!$A:$A,0)),"Review")) | F19: 126.48 | G19: 1006.49 | H19: 2 | I19: =IF(OR(D19="Uncategorised",E19=""),"Check","")
A20: Amex Sep-2024 | B20: 45536 | C20: LOOKOPTIC LOS ANGELES | D20: =IFERROR(INDEX('Review Items'!$D:$D,MATCH(C20,'Review Items'!$B:$B,0)),IFERROR(INDEX('Rule Updates'!$B:$B,MATCH(C20,'Rule Updates'!$A:$A,0)),"Uncategorised")) | E20: =IFERROR(INDEX('Review Items'!$E:$E,MATCH(C20,'Review Items'!$B:$B,0)),IFERROR(INDEX('Rule Updates'!$C:$C,MATCH(C20,'Rule Updates'!$A:$A,0)),"Review")) | F20: 55.85 | G20: 444.43 | H20: 2 | I20: =IF(OR(D20="Uncategorised",E20=""),"Check","")
A21: Amex Sep-2024 | B21: 45537 | C21: APPLE.COM/BILL CUPERTINO | D21: =IFERROR(INDEX('Review Items'!$D:$D,MATCH(C21,'Review Items'!$B:$B,0)),IFERROR(INDEX('Rule Updates'!$B:$B,MATCH(C21,'Rule Updates'!$A:$A,0)),"Uncategorised")) | E21: =IFERROR(INDEX('Review Items'!$E:$E,MATCH(C21,'Review Items'!$B:$B,0)),IFERROR(INDEX('Rule Updates'!$C:$C,MATCH(C21,'Rule Updates'!$A:$A,0)),"Review")) | F21: 11.99 | G21: 95.37 | H21: 2 | I21: =IF(OR(D21="Uncategorised",E21=""),"Check","")
A22: Amex Sep-2024 | B22: 45538 | C22: AMAZON PRIME*7M54I5JM5 AMZN.CO.UK/PM | D22: =IFERROR(INDEX('Review Items'!$D:$D,MATCH(C22,'Review Items'!$B:$B,0)),IFERROR(INDEX('Rule Updates'!$B:$B,MATCH(C22,'Rule Updates'!$A:$A,0)),"Uncategorised")) | E22: =IFERROR(INDEX('Review Items'!$E:$E,MATCH(C22,'Review Items'!$B:$B,0)),IFERROR(INDEX('Rule Updates'!$C:$C,MATCH(C22,'Rule Updates'!$A:$A,0)),"Review")) | F22: 8.99 | G22: 94.09 | H22: 3 | I22: =IF(OR(D22="Uncategorised",E22=""),"Check","")
A23: Amex Sep-2024 | B23: 45538 | C23: CITY'SUPER CENTRAL | D23: =IFERROR(INDEX('Review Items'!$D:$D,MATCH(C23,'Review Items'!$B:$B,0)),IFERROR(INDEX('Rule Updates'!$B:$B,MATCH(C23,'Rule Updates'!$A:$A,0)),"Uncategorised")) | E23: =IFERROR(INDEX('Review Items'!$E:$E,MATCH(C23,'Review Items'!$B:$B,0)),IFERROR(INDEX('Rule Updates'!$C:$C,MATCH(C23,'Rule Updates'!$A:$A,0)),"Review")) | G23: 3308.2 | H23: 2 | I23: =IF(OR(D23="Uncategorised",E23=""),"Check","")
A24: Amex Sep-2024 | B24: 45540 | C24: MINDNLIFE LIMITED SUITE 1202 | D24: =IFERROR(INDEX('Review Items'!$D:$D,MATCH(C24,'Review Items'!$B:$B,0)),IFERROR(INDEX('Rule Updates'!$B:$B,MATCH(C24,'Rule Updates'!$A:$A,0)),"Uncategorised")) | E24: =IFERROR(INDEX('Review Items'!$E:$E,MATCH(C24,'Review Items'!$B:$B,0)),IFERROR(INDEX('Rule Updates'!$C:$C,MATCH(C24,'Rule Updates'!$A:$A,0)),"Review")) | G24: 2400 | H24: 3 | I24: =IF(OR(D24="Uncategorised",E24=""),"Check","")
A25: Amex Sep-2024 | B25: 45540 | C25: OUTDOOR VOICES AUSTIN | D25: =IFERROR(INDEX('Review Items'!$D:$D,MATCH(C25,'Review Items'!$B:$B,0)),IFERROR(INDEX('Rule Updates'!$B:$B,MATCH(C25,'Rule Updates'!$A:$A,0)),"Uncategorised")) | E25: =IFERROR(INDEX('Review Items'!$E:$E,MATCH(C25,'Review Items'!$B:$B,0)),IFERROR(INDEX('Rule Updates'!$C:$C,MATCH(C25,'Rule Updates'!$A:$A,0)),"Review")) | F25: 87.5 | G25: 695.83 | H25: 3 | I25: =IF(OR(D25="Uncategorised",E25=""),"Check","")
A26: Amex Sep-2024 | B26: 45540 | C26: PAYMENT RECEIVED THROUGH AUTOPAY | D26: =IFERROR(INDEX('Review Items'!$D:$D,MATCH(C26,'Review Items'!$B:$B,0)),IFERROR(INDEX('Rule Updates'!$B:$B,MATCH(C26,'Rule Updates'!$A:$A,0)),"Uncategorised")) | E26: =IFERROR(INDEX('Review Items'!$E:$E,MATCH(C26,'Review Items'!$B:$B,0)),IFERROR(INDEX('Rule Updates'!$C:$C,MATCH(C26,'Rule Updates'!$A:$A,0)),"Review")) | G26: -238651.88 | H26: 1 | I26: =IF(OR(D26="Uncategorised",E26=""),"Check","")
A27: Amex Sep-2024 | B27: 45541 | C27: ASIA MILES LIMITED HONG KONG | D27: =IFERROR(INDEX('Review Items'!$D:$D,MATCH(C27,'Review Items'!$B:$B,0)),IFERROR(INDEX('Rule Updates'!$B:$B,MATCH(C27,'Rule Updates'!$A:$A,0)),"Uncategorised")) | E27: =IFERROR(INDEX('Review Items'!$E:$E,MATCH(C27,'Review Items'!$B:$B,0)),IFERROR(INDEX('Rule Updates'!$C:$C,MATCH(C27,'Rule Updates'!$A:$A,0)),"Review")) | G27: -2733 | H27: 3 | I27: =IF(OR(D27="Uncategorised",E27=""),"Check","")
A28: Amex Sep-2024 | B28: 45545 | C28: AMAZON PRIME*BV1JF4LD5 AMZN.CO.UK/PM | D28: =IFERROR(INDEX('Review Items'!$D:$D,MATCH(C28,'Review Items'!$B:$B,0)),IFERROR(INDEX('Rule Updates'!$B:$B,MATCH(C28,'Rule Updates'!$A:$A,0)),"Uncategorised")) | E28: =IFERROR(INDEX('Review Items'!$E:$E,MATCH(C28,'Review Items'!$B:$B,0)),IFERROR(INDEX('Rule Updates'!$C:$C,MATCH(C28,'Rule Updates'!$A:$A,0)),"Review")) | F28: 8.99 | G28: 93.75 | H28: 3 | I28: =IF(OR(D28="Uncategorised",E28=""),"Check","")
A29: Amex Sep-2024 | B29: 45545 | C29: SILVERSEA LONDON | D29: =IFERROR(INDEX('Review Items'!$D:$D,MATCH(C29,'Review Items'!$B:$B,0)),IFERROR(INDEX('Rule Updates'!$B:$B,MATCH(C29,'Rule Updates'!$A:$A,0)),"Uncategorised")) | E29: =IFERROR(INDEX('Review Items'!$E:$E,MATCH(C29,'Review Items'!$B:$B,0)),IFERROR(INDEX('Rule Updates'!$C:$C,MATCH(C29,'Rule Updates'!$A:$A,0)),"Review")) | F29: 30250 | G29: 240598.03 | H29: 3 | I29: =IF(OR(D29="Uncategorised",E29=""),"Check","")
A30: Amex Sep-2024 | B30: 45545 | C30: SILVERSEA LONDON | D30: =IFERROR(INDEX('Review Items'!$D:$D,MATCH(C30,'Review Items'!$B:$B,0)),IFERROR(INDEX('Rule Updates'!$B:$B,MATCH(C30,'Rule Updates'!$A:$A,0)),"Uncategorised")) | E30: =IFERROR(INDEX('Review Items'!$E:$E,MATCH(C30,'Review Items'!$B:$B,0)),IFERROR(INDEX('Rule Updates'!$C:$C,MATCH(C30,'Rule Updates'!$A:$A,0)),"Review")) | F30: 24550 | G30: 195262.21 | H30: 3 | I30: =IF(OR(D30="Uncategorised",E30=""),"Check","")
A31: Amex Sep-2024 | B31: 45545 | C31: SILVERSEA LONDON | D31: =IFERROR(INDEX('Review Items'!$D:$D,MATCH(C31,'Review Items'!$B:$B,0)),IFERROR(INDEX('Rule Updates'!$B:$B,MATCH(C31,'Rule Updates'!$A:$A,0)),"Uncategorised")) | E31: =IFERROR(INDEX('Review Items'!$E:$E,MATCH(C31,'Review Items'!$B:$B,0)),IFERROR(INDEX('Rule Updates'!$C:$C,MATCH(C31,'Rule Updates'!$A:$A,0)),"Review")) | F31: 26050 | G31: 207192.69 | H31: 3 | I31: =IF(OR(D31="Uncategorised",E31=""),"Check","")
A32: Amex Sep-2024 | B32: 45545 | C32: SILVERSEA LONDON | D32: =IFERROR(INDEX('Review Items'!$D:$D,MATCH(C32,'Review Items'!$B:$B,0)),IFERROR(INDEX('Rule Updates'!$B:$B,MATCH(C32,'Rule Updates'!$A:$A,0)),"Uncategorised")) | E32: =IFERROR(INDEX('Review Items'!$E:$E,MATCH(C32,'Review Items'!$B:$B,0)),IFERROR(INDEX('Rule Updates'!$C:$C,MATCH(C32,'Rule Updates'!$A:$A,0)),"Review")) | F32: 26000 | G32: 206795 | H32: 3 | I32: =IF(OR(D32="Uncategorised",E32=""),"Check","")
A33: Amex Sep-2024 | B33: 45545 | C33: SILVERSEA LONDON | D33: =IFERROR(INDEX('Review Items'!$D:$D,MATCH(C33,'Review Items'!$B:$B,0)),IFERROR(INDEX('Rule Updates'!$B:$B,MATCH(C33,'Rule Updates'!$A:$A,0)),"Uncategorised")) | E33: =IFERROR(INDEX('Review Items'!$E:$E,MATCH(C33,'Review Items'!$B:$B,0)),IFERROR(INDEX('Rule Updates'!$C:$C,MATCH(C33,'Rule Updates'!$A:$A,0)),"Review")) | F33: 14290 | G33: 113657.71 | H33: 3 | I33: =IF(OR(D33="Uncategorised",E33=""),"Check","")
A34: Amex Sep-2024 | B34: 45545 | C34: SILVERSEA LONDON | D34: =IFERROR(INDEX('Review Items'!$D:$D,MATCH(C34,'Review Items'!$B:$B,0)),IFERROR(INDEX('Rule Updates'!$B:$B,MATCH(C34,'Rule Updates'!$A:$A,0)),"Uncategorised")) | E34: =IFERROR(INDEX('Review Items'!$E:$E,MATCH(C34,'Review Items'!$B:$B,0)),IFERROR(INDEX('Rule Updates'!$C:$C,MATCH(C34,'Rule Updates'!$A:$A,0)),"Review")) | F34: 26050 | G34: 207192.69 | H34: 3 | I34: =IF(OR(D34="Uncategorised",E34=""),"Check","")
A35: Amex Sep-2024 | B35: 45545 | C35: SILVERSEA LONDON | D35: =IFERROR(INDEX('Review Items'!$D:$D,MATCH(C35,'Review Items'!$B:$B,0)),IFERROR(INDEX('Rule Updates'!$B:$B,MATCH(C35,'Rule Updates'!$A:$A,0)),"Uncategorised")) | E35: =IFERROR(INDEX('Review Items'!$E:$E,MATCH(C35,'Review Items'!$B:$B,0)),IFERROR(INDEX('Rule Updates'!$C:$C,MATCH(C35,'Rule Updates'!$A:$A,0)),"Review")) | F35: 2112 | G35: 16798.11 | H35: 3 | I35: =IF(OR(D35="Uncategorised",E35=""),"Check","")
A36: Amex Sep-2024 | B36: 45545 | C36: SILVERSEA LONDON | D36: =IFERROR(INDEX('Review Items'!$D:$D,MATCH(C36,'Review Items'!$B:$B,0)),IFERROR(INDEX('Rule Updates'!$B:$B,MATCH(C36,'Rule Updates'!$A:$A,0)),"Uncategorised")) | E36: =IFERROR(INDEX('Review Items'!$E:$E,MATCH(C36,'Review Items'!$B:$B,0)),IFERROR(INDEX('Rule Updates'!$C:$C,MATCH(C36,'Rule Updates'!$A:$A,0)),"Review")) | F36: 11968 | G36: 95189.32 | H36: 3 | I36: =IF(OR(D36="Uncategorised",E36=""),"Check","")
A37: Amex Sep-2024 | B37: 45546 | C37: BAR LEONE SHEUNG WAN | D37: =IFERROR(INDEX('Review Items'!$D:$D,MATCH(C37,'Review Items'!$B:$B,0)),IFERROR(INDEX('Rule Updates'!$B:$B,MATCH(C37,'Rule Updates'!$A:$A,0)),"Uncategorised")) | E37: =IFERROR(INDEX('Review Items'!$E:$E,MATCH(C37,'Review Items'!$B:$B,0)),IFERROR(INDEX('Rule Updates'!$C:$C,MATCH(C37,'Rule Updates'!$A:$A,0)),"Review")) | G37: 2963 | H37: 3 | I37: =IF(OR(D37="Uncategorised",E37=""),"Check","")
A38: Amex Sep-2024 | B38: 45546 | C38: GARMIN (EUROPE) LIMITED SOUTHAMPTON | D38: =IFERROR(INDEX('Review Items'!$D:$D,MATCH(C38,'Review Items'!$B:$B,0)),IFERROR(INDEX('Rule Updates'!$B:$B,MATCH(C38,'Rule Updates'!$A:$A,0)),"Uncategorised")) | E38: =IFERROR(INDEX('Review Items'!$E:$E,MATCH(C38,'Review Items'!$B:$B,0)),IFERROR(INDEX('Rule Updates'!$C:$C,MATCH(C38,'Rule Updates'!$A:$A,0)),"Review")) | F38: 9.99 | G38: 79.45 | H38: 3 | I38: =IF(OR(D38="Uncategorised",E38=""),"Check","")
A39: Amex Sep-2024 | B39: 45546 | C39: KITH Cafe ASCOTT ORCHAR SINGAPORE | D39: =IFERROR(INDEX('Review Items'!$D:$D,MATCH(C39,'Review Items'!$B:$B,0)),IFERROR(INDEX('Rule Updates'!$B:$B,MATCH(C39,'Rule Updates'!$A:$A,0)),"Uncategorised")) | E39: =IFERROR(INDEX('Review Items'!$E:$E,MATCH(C39,'Review Items'!$B:$B,0)),IFERROR(INDEX('Rule Updates'!$C:$C,MATCH(C39,'Rule Updates'!$A:$A,0)),"Review")) | F39: 22.13 | G39: 134.96 | H39: 6 | I39: =IF(OR(D39="Uncategorised",E39=""),"Check","")
A40: Amex Sep-2024 | B40: 45546 | C40: KITH Cafe ASCOTT ORCHAR SINGAPORE | D40: =IFERROR(INDEX('Review Items'!$D:$D,MATCH(C40,'Review Items'!$B:$B,0)),IFERROR(INDEX('Rule Updates'!$B:$B,MATCH(C40,'Rule Updates'!$A:$A,0)),"Uncategorised")) | E40: =IFERROR(INDEX('Review Items'!$E:$E,MATCH(C40,'Review Items'!$B:$B,0)),IFERROR(INDEX('Rule Updates'!$C:$C,MATCH(C40,'Rule Updates'!$A:$A,0)),"Review")) | F40: 7.14 | G40: 43.58 | H40: 6 | I40: =IF(OR(D40="Uncategorised",E40=""),"Check","")
A41: Amex Sep-2024 | B41: 45546 | C41: KPAY*MOMOGAWANOU 000000 HONG KONG | D41: =IFERROR(INDEX('Review Items'!$D:$D,MATCH(C41,'Review Items'!$B:$B,0)),IFERROR(INDEX('Rule Updates'!$B:$B,MATCH(C41,'Rule Updates'!$A:$A,0)),"Uncategorised")) | E41: =IFERROR(INDEX('Review Items'!$E:$E,MATCH(C41,'Review Items'!$B:$B,0)),IFERROR(INDEX('Rule Updates'!$C:$C,MATCH(C41,'Rule Updates'!$A:$A,0)),"Review")) | G41: 3340 | H41: 4 | I41: =IF(OR(D41="Uncategorised",E41=""),"Check","")
...

Sheet Rule Updates
A1: Rule Updates
A2: Use the dropdowns here to maintain merchant rules for future imports.
A4: Merchant | B4: Category | C4: Belongs To | D4: In Category? | E4: Suggested Match Text | F4: Action
A5: SILVERSEA LONDON | B5: Travel | C5: Family | D5: =IF(COUNTIF(Category!$A:$A,E5)>0,"Yes","No") | E5: =LEFT(A5,80) | F5: =IF(OR(B5="Uncategorised",C5="",C5="Review"),"Needs category/owner",IF(D5="Yes","Already in Category","Add to Category"))
A6: THE NET-A-PORTER GROUP HONG KONG | B6: Clothes & Shoes | C6: Su | D6: =IF(COUNTIF(Category!$A:$A,E6)>0,"Yes","No") | E6: =LEFT(A6,80) | F6: =IF(OR(B6="Uncategorised",C6="",C6="Review"),"Needs category/owner",IF(D6="Yes","Already in Category","Add to Category"))
A7: MYTHERESA APAC SERVICES ISLANDS | B7: Clothes & Shoes | C7: Su | D7: =IF(COUNTIF(Category!$A:$A,E7)>0,"Yes","No") | E7: =LEFT(A7,80) | F7: =IF(OR(B7="Uncategorised",C7="",C7="Review"),"Needs category/owner",IF(D7="Yes","Already in Category","Add to Category"))
A8: HTL*ASCOTTORCHARDS 800-468-3578 | B8: Hotel | C8: Family | D8: =IF(COUNTIF(Category!$A:$A,E8)>0,"Yes","No") | E8: =LEFT(A8,80) | F8: =IF(OR(B8="Uncategorised",C8="",C8="Review"),"Needs category/owner",IF(D8="Yes","Already in Category","Add to Category"))
A9: WHALE CLU BHK | B9: Dining out | C9: Family | D9: =IF(COUNTIF(Category!$A:$A,E9)>0,"Yes","No") | E9: =LEFT(A9,80) | F9: =IF(OR(B9="Uncategorised",C9="",C9="Review"),"Needs category/owner",IF(D9="Yes","Already in Category","Add to Category"))
A10: PONTI WINE CELLARS 0000 HONG KONG | B10: Wine | C10: Family | D10: =IF(COUNTIF(Category!$A:$A,E10)>0,"Yes","No") | E10: =LEFT(A10,80) | F10: =IF(OR(B10="Uncategorised",C10="",C10="Review"),"Needs category/owner",IF(D10="Yes","Already in Category","Add to Category"))
A11: LANE CRAWFORD (FURNITUR ADMIRALTY | B11: Housewares | C11: Family | D11: =IF(COUNTIF(Category!$A:$A,E11)>0,"Yes","No") | E11: =LEFT(A11,80) | F11: =IF(OR(B11="Uncategorised",C11="",C11="Review"),"Needs category/owner",IF(D11="Yes","Already in Category","Add to Category"))
A12: RAFFLES HOTEL SINGAPORE SINGAPORE | B12: Uncategorised | C12: Review | D12: =IF(COUNTIF(Category!$A:$A,E12)>0,"Yes","No") | E12: =LEFT(A12,80) | F12: =IF(OR(B12="Uncategorised",C12="",C12="Review"),"Needs category/owner",IF(D12="Yes","Already in Category","Add to Category"))
A13: AGORA IBIZA 367352630 SANT JOAN LAB | B13: Hotel | C13: Family | D13: =IF(COUNTIF(Category!$A:$A,E13)>0,"Yes","No") | E13: =LEFT(A13,80) | F13: =IF(OR(B13="Uncategorised",C13="",C13="Review"),"Needs category/owner",IF(D13="Yes","Already in Category","Add to Category"))
A14: FAR FETCH LONDON | B14: Clothes & Shoes | C14: Su | D14: =IF(COUNTIF(Category!$A:$A,E14)>0,"Yes","No") | E14: =LEFT(A14,80) | F14: =IF(OR(B14="Uncategorised",C14="",C14="Review"),"Needs category/owner",IF(D14="Yes","Already in Category","Add to Category"))
A15: BURGUNDY ETC CENTRAL | B15: Wine | C15: Family | D15: =IF(COUNTIF(Category!$A:$A,E15)>0,"Yes","No") | E15: =LEFT(A15,80) | F15: =IF(OR(B15="Uncategorised",C15="",C15="Review"),"Needs category/owner",IF(D15="Yes","Already in Category","Add to Category"))
A16: 3CPAYMENT*SIX SENSES IB GETARIA | B16: Hotel | C16: Family | D16: =IF(COUNTIF(Category!$A:$A,E16)>0,"Yes","No") | E16: =LEFT(A16,80) | F16: =IF(OR(B16="Uncategorised",C16="",C16="Review"),"Needs category/owner",IF(D16="Yes","Already in Category","Add to Category"))
... A692: TUMI ASIA LIMITED | B692: Uncategorised | C692: Review | D692: =IF(COUNTIF(Category!$A:$A,E692)>0,"Yes","No") | E692: =LEFT(A692,80) | F692: =IF(OR(B692="Uncategorised",C692="",C692="Review"),"Needs category/owner",IF(D692="Yes","Already in Category","Add to Category"))

Sheet Lists
A1: Categories | B1: Belongs To
A2: Airfare | B2: Family
A3: Art | B3: Payment
A4: Beauty | B4: Review
A5: Book & Kindle | B5: Su
A6: Charity
A7: Clinic
A8: Clothes & Shoes
A9: Dining out
A10: Electronics
A11: Entertainment
A12: Fees
A13: Fitness Equipment
A14: Flowers
A15: Food
A16: Glasses
A17: Groceries
... A36: beauty

Sheet Category
A1: Match Text | B1: Category | C1: Belongs To
A2: 10 Green Street | B2: Pharmacy | C2: Su
A3: 45R | B3: Clothes & Shoes | C3: Su
A4: 5 Hertford Street Limited | B4: Dining out | C4: Family
A5: Agolde | B5: Clothes & Shoes | C5: Su
A6: Amathus | B6: Dining out | C6: Family
A7: BA & SH | B7: Clothes & Shoes | C7: Su
A8: Bloomingdales | B8: Clothes & Shoes | C8: Su
A9: Blue Ojai | B9: Housewares | C9: Family
A10: Born in the sun | B10: Clothes & Shoes | C10: Su
A11: Caddis | B11: Glasses | C11: Su
A12: Cettire | B12: Clothes & Shoes | C12: Su
... A258: NEW CHITOSE | B258: Travel | C258: Family
